Workbook

Sheet COVER
A1: Asian Paints Limited (NSE: ASIANPAINT)
A2: Valuation date: 31 March 2026
A3: All figures in ₹ crore
A4: Share price used: ₹2,164.50
A5: Method: unlevered DCF, five-year forecast plus terminal value
A6: Prepared by: Neev Hiranandani

Sheet Source Tie-Out
A1: Source Tie-Out — Uploaded Asian Paints Annual Reports
A3: Tie-out item | B3: FY20 2019-20 | C3: FY21 2020-21 | D3: FY22 2021-22 | E3: FY23 2022-23 | F3: FY24 2023-24 | G3: FY25 2024-25 | H3: FY26 2025-26 | J3: Model year | K3: Financial year | L3: Uploaded source file | M3: Statement / pages used
A4: Total assets | B4: ='Historical BS'!C24 -> 16154.77 | C4: ='Historical BS'!D24 -> 20369.62 | D4: ='Historical BS'!E24 -> 22984.45 | E4: ='Historical BS'!F24 -> 25798 | F4: ='Historical BS'!G24 -> 29924.09 | G4: ='Historical BS'!H24 -> 30371.37 | H4: ='Historical BS'!I24 -> 34534.49 | J4: FY20 | K4: 2019-20 | L4: FINAL-Asian-Paints-IR-2020-21-online-30621.pdf | M4: Consolidated BS p. 262-263; Consolidated CFS p. 268-269
A5: Total equity and liabilities | B5: ='Historical BS'!C25 -> 16154.77 | C5: ='Historical BS'!D25 -> 20369.62 | D5: ='Historical BS'!E25 -> 22984.45 | E5: ='Historical BS'!F25 -> 25798 | F5: ='Historical BS'!G25 -> 29924.09 | G5: ='Historical BS'!H25 -> 30371.37 | H5: ='Historical BS'!I25 -> 34534.49 | J5: FY21 | K5: 2020-21 | L5: FINAL-Asian-Paints-IR-2020-21-online-30621.pdf | M5: Consolidated BS p. 262-263; Consolidated CFS p. 268-269
A6: BS check | B6: =B4-B5 -> 0 | C6: =C4-C5 -> 0 | D6: =D4-D5 -> 0 | E6: =E4-E5 -> 0 | F6: =F4-F5 -> 0 | G6: =G4-G5 -> 0 | H6: =H4-H5 -> 0 | J6: FY22 | K6: 2021-22 | L6: AsianpaintsIntegratedReportFY2022.pdf | M6: Consolidated BS p. 294-295; Consolidated CFS p. 300-301
A7: CFO | B7: ='Historical Cash Flow'!C5 -> 3038.15 | C7: ='Historical Cash Flow'!D5 -> 3683.35 | D7: ='Historical Cash Flow'!E5 -> 986.49 | E7: ='Historical Cash Flow'!F5 -> 4193.43 | F7: ='Historical Cash Flow'!G5 -> 6103.6 | G7: ='Historical Cash Flow'!H5 -> 4423.96 | H7: ='Historical Cash Flow'!I5 -> 7088.18 | J7: FY23 | K7: 2022-23 | L7: Asian_PaintsIR22-23.pdf | M7: Consolidated BS p. 374-375; Consolidated CFS p. 380-381
A8: Gross capex for DCF | B8: ='Historical Cash Flow'!C22 -> 403.54 | C8: ='Historical Cash Flow'!D22 -> 281.87 | D8: ='Historical Cash Flow'!E22 -> 538.24 | E8: ='Historical Cash Flow'!F22 -> 1273.37 | F8: ='Historical Cash Flow'!G22 -> 2199.01 | G8: ='Historical Cash Flow'!H22 -> 1805.32 | H8: ='Historical Cash Flow'!I22 -> 1467.02 | J8: FY24 | K8: 2023-24 | L8: Asian_Paints_FY24_AnnualReport.pdf | M8: Consolidated BS p. 410-413; Consolidated CFS p. 418-419
A9: FCF check: CFO - gross capex | B9: ='Historical Cash Flow'!C24 -> 2634.61 | C9: ='Historical Cash Flow'!D24 -> 3401.48 | D9: ='Historical Cash Flow'!E24 -> 448.25 | E9: ='Historical Cash Flow'!F24 -> 2920.06 | F9: ='Historical Cash Flow'!G24 -> 3904.59 | G9: ='Historical Cash Flow'!H24 -> 2618.64 | H9: ='Historical Cash Flow'!I24 -> 5621.16 | J9: FY25 | K9: 2024-25 | L9: Integrated-Annual-Report-FY_2024-25.pdf | M9: Consolidated BS p. 440-441; Consolidated CFS p. 446-447
J10: FY26 | K10: 2025-26 | L10: Integrated-Annual-Report-2025-26.pdf | M10: Consolidated BS p. 460-461; Consolidated CFS p. 466-467

Sheet Historical P&L
A1: Profit & Loss Statement — Consolidated
A2: Units — ₹ Crores
A5: P&L item | B5: FY20 2019-20 | C5: FY21 2020-21 | D5: FY22 2021-22 | E5: FY23 2022-23 | F5: FY24 2023-24 | G5: FY25 2024-25 | H5: FY26 2025-26
A6: Revenue from operations (Goods & Services) | B6: =20025.96+22.36 -> 20048.32 | C6: =21440.24+44.96 -> 21485.2 | D6: =28830.02+93.46 -> 28923.48 | E6: =34253.35+114.48 -> 34367.83 | F6: =35248.88+133.24 -> 35382.12 | G6: =33626.82+170.54 -> 33797.36 | H6: =35416.25+100.12 -> 35516.37
A7: Other operating income, if any | B7: 162.93 | C7: 227.59 | D7: 177.8 | E7: 120.76 | F7: 112.61 | G7: 108.26 | H7: 67.17
A8: Total Operating Revenue | B8: =SUM(B6:B7) -> 20211.25 | C8: =SUM(C6:C7) -> 21712.79 | D8: =SUM(D6:D7) -> 29101.28 | E8: =SUM(E6:E7) -> 34488.59 | F8: =SUM(F6:F7) -> 35494.73 | G8: =SUM(G6:G7) -> 33905.62 | H8: =SUM(H6:H7) -> 35583.54
A9: Raw material cost / COGS | B9: -10091.78 | C9: -10317.09 | D9: -16254.59 | E9: -17330.58 | F9: -15868.21 | G9: -15793.92 | H9: -15384.05
A10: Purchases of stock-in-trade | B10: -1530.83 | C10: -1872.59 | D10: -3371.13 | E10: -4135.65 | F10: -3858.2 | G10: -3926.86 | H10: -4014.05
A11: Change in inventories | B11: 239.15 | C11: 92.45 | D11: 1324.97 | E11: 309.73 | F11: -363.8 | G11: 205 | H11: -603.68
A12: Employee benefit expenses | B12: -1366.09 | C12: -1540.75 | D12: -1786.67 | E12: -2028.07 | F12: -2326.18 | G12: -2597.23 | H12: -2799.59
A13: Other operating expenses | B13: -3299.93 | C13: -3219.21 | D13: -4210.25 | E13: -5044.18 | F13: -5493.36 | G13: -5786.4 | H13: -6086.25
A14: Total Operating Expenses | B14: =SUM(B9:B13) -> -16049.48 | C14: =SUM(C9:C13) -> -16857.19 | D14: =SUM(D9:D13) -> -24297.67 | E14: =SUM(E9:E13) -> -28228.75 | F14: =SUM(F9:F13) -> -27909.75 | G14: =SUM(G9:G13) -> -27899.41 | H14: =SUM(H9:H13) -> -28887.62
A15: EBITDA | B15: =B8+B14 -> 4161.77 | C15: =C8+C14 -> 4855.6 | D15: =D8+D14 -> 4803.61 | E15: =E8+E14 -> 6259.84 | F15: =F8+F14 -> 7584.98 | G15: =G8+G14 -> 6006.21 | H15: =H8+H14 -> 6695.92
A16: Depreciation & amortisation | B16: -780.5 | C16: -791.27 | D16: -816.36 | E16: -858.02 | F16: -853 | G16: -1026.34 | H16: -1228.85
A17: EBIT | B17: =B15+B16 -> 3381.27 | C17: =C15+C16 -> 4064.33 | D17: =D15+D16 -> 3987.25 | E17: =E15+E16 -> 5401.82 | F17: =F15+F16 -> 6731.98 | G17: =G15+G16 -> 4979.87 | H17: =H15+H16 -> 5467.07
A18: Other income | B18: 304.31 | C18: 303.05 | D18: 380.01 | E18: 386.48 | F18: 687.96 | G18: 572.61 | H18: 723.8
A19: Finance cost | B19: -102.33 | C19: -91.63 | D19: -95.41 | E19: -144.45 | F19: -205.17 | G19: -227.02 | H19: -195.41
A20: Exceptional items | B20: 0 | C20: 0 | D20: -115.7 | E20: -48.87 | F20: 0 | G20: -363.1 | H20: -157.61
A21: Share of profit in Associates | B21: 50.74 | C21: 28.6 | D21: 31.57 | E21: 93.85 | F21: 133 | G21: 140.71 | H21: 165.59
A22: Profit before tax | B22: =SUM(B17:B21) -> 3633.99 | C22: =SUM(C17:C21) -> 4304.35 | D22: =SUM(D17:D21) -> 4187.72 | E22: =SUM(E17:E21) -> 5688.83 | F22: =SUM(F17:F21) -> 7347.77 | G22: =SUM(G17:G21) -> 5103.07 | H22: =SUM(H17:H21) -> 6003.44
A23: Tax expense | B23: -854.85 | C23: -1097.6 | D23: -1102.91 | E23: -1493.5 | F23: -1790.08 | G23: -1393.36 | H23: -1608.75
A24: PAT / net profit | B24: =SUM(B22:B23) -> 2779.14 | C24: =SUM(C22:C23) -> 3206.75 | D24: =SUM(D22:D23) -> 3084.81 | E24: =SUM(E22:E23) -> 4195.33 | F24: =SUM(F22:F23) -> 5557.69 | G24: =SUM(G22:G23) -> 3709.71 | H24: =SUM(H22:H23) -> 4394.69
A26: Tax Rate (%) | B26: =-B23/B22 -> 0.2352373 | C26: =-C23/C22 -> 0.25499785 | D26: =-D23/D22 -> 0.26336766 | E26: =-E23/E22 -> 0.26253201 | F26: =-F23/F22 -> 0.24362221 | G26: =-G23/G22 -> 0.27304348 | H26: =-H23/H22 -> 0.26797136

Sheet Historical BS
A1: Historical Balance Sheet — Consolidated
A2: Units — ₹ Crores
A4: BS item | B4: Source / treatment | C4: FY20 2019-20 | D4: FY21 2020-21 | E4: FY22 2021-22 | F4: FY23 2022-23 | G4: FY24 2023-24 | H4: FY25 2024-25 | I4: FY26 2025-26 | J4: Operating Asset or Not
A5: Cash and cash equivalents | B5: Direct BS line: Cash and Cash Equivalents | C5: 563.83 | D5: 346.39 | E5: 621.72 | F5: 523.1 | G5: 829.34 | H5: 445.28 | I5: 672.83 | J5: Operating Asset but not included in forecasting
A6: Current investments | B6: Current Financial Assets - Investments | C6: 512.48 | D6: 3267.12 | E6: 2180.7 | F6: 2697 | G6: 3203.41 | H6: 3244.96 | I6: 6285.83 | J6: Non-operating asset
A7: Trade receivables | B7: Current trade receivables only; non-current trade receivables excluded | C7: 1795.22 | D7: 2602.17 | E7: 3871.44 | F7: 4636.94 | G7: 4889.05 | H7: 4313.65 | I7: 4461.8 | J7: Operating Asset but not included in forecasting
A8: Inventories | B8: Direct BS line | C8: 3389.81 | D8: 3798.6 | E8: 6152.98 | F8: 6210.64 | G8: 5923.41 | H8: 6719.27 | I8: 5743.69 | J8: Operating Asset
A9: Other current assets | B9: Direct BS line: Other Current Assets; excludes cash, investments, other financial assets | C9: 285.59 | D9: 537.23 | E9: 541.25 | F9: 553.98 | G9: 785.83 | H9: 773.71 | I9: 796.51 | J9: Non-operating asset
A10: Net PP&E | B10: Direct BS line: Property, Plant and Equipment | C10: 4764.76 | D10: 4476.35 | E10: 4184.46 | F10: 4145.65 | G10: 4446.2 | H10: 6787.62 | I10: 7146.23 | J10: Operating Asset
A11: Other intangible assets (excl. goodwill) | B11: Direct BS line: Other Intangible Assets only; goodwill excluded from depreciable base | C11: 267.47 | D11: 233.99 | E11: 185.99 | F11: 187.41 | G11: 424.96 | H11: 369.18 | I11: 256.2 | J11: Operating Asset; included in depreciable base; goodwill excluded
A12: Right-of-use assets | B12: Direct BS line: Right-of-Use Assets | C12: 920.09 | D12: 845.55 | E12: 905.75 | F12: 1208.92 | G12: 1856.27 | H12: 1843.72 | I12: 2018.77 | J12: Operating Asset
A13: Trade payables | B13: MSME dues + creditors other than MSME | C13: 2136.57 | D13: 3378.72 | E13: 4164.3 | F13: 3635.44 | G13: 3831.34 | H13: 3848 | I13: 3863.04 | J13: Operating Liability
A14: Other current liabilities | B14: Other Financial Liabilities + Other Current Liabilities + Provisions; excludes borrowings, lease and tax | C14: 1568.41 | D14: 1917.03 | E14: 2332.6 | F14: 2969.27 | G14: 3222.4 | H14: 3259.77 | I14: 3719.16 | J14: Non-operating Liabilitiy
A15: Short-term borrowings | B15: Current Financial Liabilities - Borrowings | C15: 321.48 | D15: 325.7 | E15: 731.12 | F15: 896.06 | G15: 1052.76 | H15: 604.13 | I15: 1046.09 | J15: Operating Liability
A16: Current maturities of long-term debt | B16: Not separately disclosed in main BS; included within current borrowings if applicable | C16: 0 | D16: 0 | E16: 0 | F16: 0 | G16: 0 | H16: 0 | I16: 0 | J16: Operating Liability
... A23: Other balances with banks | B23: Direct BS line: Other Balances with Banks | C23: 219 | D23: 264.36 | E23: 242.61 | F23: 320.72 | G23: 254.67 | H23: 336.7 | I23: 400.85 | J23: Non-operating asset
A24: Total assets - report check | B24: Direct BS line: Total Assets | C24: 16154.77 | D24: 20369.62 | E24: 22984.45 | F24: 25798 | G24: 29924.09 | H24: 30371.37 | I24: 34534.49
A25: Total equity and liabilities - report check | B25: Direct BS line: Total Equity and Liabilities | C25: 16154.77 | D25: 20369.62 | E25: 22984.45 | F25: 25798 | G25: 29924.09 | H25: 30371.37 | I25: 34534.49
A26: Operating NWC | B26: Trade receivables + Inventories + Other current assets - Trade payables - Other current liabilities | C26: =C7+C8+C9-C13-C14 -> 1765.64 | D26: =D7+D8+D9-D13-D14 -> 1642.25 | E26: =E7+E8+E9-E13-E14 -> 4068.77 | F26: =F7+F8+F9-F13-F14 -> 4796.85 | G26: =G7+G8+G9-G13-G14 -> 4544.55 | H26: =H7+H8+H9-H13-H14 -> 4698.86 | I26: =I7+I8+I9-I13-I14 -> 3419.8
A27: Net debt / (cash & current investments) | B27: ST borrowings + LT borrowings + lease liabilities - cash - current investments | C27: =C15+C17+C18-C5-C6 -> 27.61 | D27: =D15+D17+D18-D5-D6 -> -2528.74 | E27: =E15+E17+E18-E5-E6 -> -1215.54 | F27: =F15+F17+F18-F5-F6 -> -1287.48 | G27: =G15+G17+G18-G5-G6 -> -1558.37 | H27: =H15+H17+H18-H5-H6 -> -1399.95 | I27: =I15+I17+I18-I5-I6 -> -3029.73

Sheet Historical Cash Flow
A1: Historical Cash Flow — Consolidated
A2: Units — ₹ Crores
A4: Cash flow item | B4: Source / treatment | C4: FY20 2019-20 | D4: FY21 2020-21 | E4: FY22 2021-22 | F4: FY23 2022-23 | G4: FY24 2023-24 | H4: FY25 2024-25 | I4: FY26 2025-26
A5: Net cash generated from operating activities / CFO | B5: Direct CFS line | C5: 3038.15 | D5: 3683.35 | E5: 986.49 | F5: 4193.43 | G5: 6103.6 | H5: 4423.96 | I5: 7088.18
A6: Purchase of PP&E and other intangible assets | B6: CFS investing section | C6: -403.54 | D6: -281.87 | E6: -538.24 | F6: -1273.37 | G6: -2199.01 | H6: -1805.32 | I6: -1467.02
A7: Sale of property, plant and equipment | B7: CFS investing section | C7: 36.6 | D7: 27.61 | E7: 39.58 | F7: 25.92 | G7: 5.13 | H7: 10.1 | I7: 3.2
A8: Payment for acquiring right-of-use assets | B8: CFS investing section | C8: -10.15 | D8: -6.84 | E8: -12.46 | F8: -172.24 | G8: -297.07 | H8: -24.75 | I8: -20.3
A9: Net cash used in investing activities | B9: Direct CFS line | C9: -521.42 | D9: -547.79 | E9: -321.69 | F9: -1274.64 | G9: -2517.63 | H9: -874.12 | I9: -1334.07
A10: Proceeds from long/non-current borrowings | B10: CFS financing section | C10: 17.91 | D10: 2.14 | E10: 39.87 | F10: 94 | G10: 5.91 | H10: 219.84 | I10: 993.41
A11: Repayment of long/non-current borrowings | B11: CFS financing section | C11: -10.49 | D11: -14.21 | E11: -7.89 | F11: -15.55 | G11: -14.17 | H11: -21.16 | I11: -32.43
A12: Proceeds/(repayment) of short/current borrowings, net | B12: CFS financing section | C12: -268.79 | D12: 37.78 | E12: 292.68 | F12: 159.76 | G12: 94.98 | H12: -406.41 | I12: 285.44
A13: Acceptances, net | B13: CFS financing section | C13: -203.13 | D13: 115.5 | E13: 85.35 | F13: -8.97 | G13: -83.65 | H13: 194.74 | I13: -419.89
A14: Repayment of principal portion of lease liabilities | B14: CFS financing section | C14: -179.07 | D14: -202.95 | E14: -221.4 | F14: -255.72 | G14: -285.63 | H14: -324.62 | I14: -339.78
A15: Finance costs paid | B15: CFS financing section | C15: -100.89 | D15: -89.31 | E15: -93.56 | F15: -141.95 | G15: -190.57 | H15: -203.19 | I15: -228.33
A16: Dividend paid | B16: CFS financing section | C16: -2120.71 | D16: -499.35 | E16: -1762.8 | F16: -1936.05 | G16: -2550.88 | H16: -3140.21 | I16: -2425.38
... A21: Cash and cash equivalents at 31 March | B21: Direct CFS line | C21: 928.75 | D21: 3421.16 | E21: 2283.29 | F21: 3054.33 | G21: 3626.95 | H21: 3357.42 | I21: 6740.86
A22: Gross capex for DCF, positive | B22: - Purchase of PP&E and other intangible assets | C22: =-C6 -> 403.54 | D22: =-D6 -> 281.87 | E22: =-E6 -> 538.24 | F22: =-F6 -> 1273.37 | G22: =-G6 -> 2199.01 | H22: =-H6 -> 1805.32 | I22: =-I6 -> 1467.02
A23: Capex incl. ROU assets, positive | B23: - (Purchase of PP&E/intangibles + ROU asset payments) | C23: =-(C6+C8) -> 413.69 | D23: =-(D6+D8) -> 288.71 | E23: =-(E6+E8) -> 550.7 | F23: =-(F6+F8) -> 1445.61 | G23: =-(G6+G8) -> 2496.08 | H23: =-(H6+H8) -> 1830.07 | I23: =-(I6+I8) -> 1487.32
A24: FCF check: CFO - gross capex | B24: CFO less gross capex; broad check against forecast FCF | C24: =C5-C22 -> 2634.61 | D24: =D5-D22 -> 3401.48 | E24: =E5-E22 -> 448.25 | F24: =F5-F22 -> 2920.06 | G24: =G5-G22 -> 3904.59 | H24: =H5-H22 -> 2618.64 | I24: =I5-I22 -> 5621.16
A25: FCF check incl. ROU: CFO - capex incl. ROU | B25: CFO less capex including ROU payments | C25: =C5-C23 -> 2624.46 | D25: =D5-D23 -> 3394.64 | E25: =E5-E23 -> 435.79 | F25: =F5-F23 -> 2747.82 | G25: =G5-G23 -> 3607.52 | H25: =H5-H23 -> 2593.89 | I25: =I5-I23 -> 5600.86

Sheet Forecast P&L
A1: Profit & Loss Statement Forecasted (NOPAT table Included)
A2: Units — ₹ Crores
A4: Case Selector | B4: 2 | D4: Case 1 | E4: Bullish
D5: Case 2 | E5: Base
D6: Case 3 | E6: Bearish
J7: Number of Forecast Years
J8: 1 | K8: 2 | L8: 3 | M8: 4 | N8: 5
A9: Years | B9: 2019-20 | C9: 2020-21 | D9: 2021-22 | E9: 2022-23 | F9: 2023-24 | G9: 2024-25 | H9: 2025-26 | J9: 2026-27 | K9: 2027-28 | L9: 2028-29 | M9: 2029-30 | N9: 2030-31 | O9: Comments
A11: Net Operating Revenue | B11: ='Historical P&L'!B8 -> 20211.25 | C11: ='Historical P&L'!C8 -> 21712.79 | D11: ='Historical P&L'!D8 -> 29101.28 | E11: ='Historical P&L'!E8 -> 34488.59 | F11: ='Historical P&L'!F8 -> 35494.73 | G11: ='Historical P&L'!G8 -> 33905.62 | H11: ='Historical P&L'!H8 -> 35583.54 | J11: =(1+J12)*H11 -> 38074.388 | K11: =(1+K12)*J11 -> 40644.409 | L11: =(1+L12)*K11 -> 43286.296 | M11: =(1+M12)*L11 -> 45991.689 | N11: =(1+N12)*M11 -> 48751.19
A12: Growth Rate (%) | C12: =C11/B11-1 -> 0.074292288 | D12: =D11/C11-1 -> 0.34028285 | E12: =E11/D11-1 -> 0.18512278 | F12: =F11/E11-1 -> 0.029173127 | G12: =G11/F11-1 -> -0.044770308 | H12: =H11/G11-1 -> 0.049487961 | J12: =CHOOSE($B$4,J14,J15,J16) -> 0.07 | K12: =CHOOSE($B$4,K14,K15,K16) -> 0.0675 | L12: =CHOOSE($B$4,L14,L15,L16) -> 0.065 | M12: =CHOOSE($B$4,M14,M15,M16) -> 0.0625 | N12: =CHOOSE($B$4,N14,N15,N16) -> 0.06
J14: =J15+2% -> 0.09 | K14: =K15+2% -> 0.0875 | L14: =L15+2% -> 0.085 | M14: =M15+2% -> 0.0825 | N14: =N15+2% -> 0.08
J15: =7%+((6%-7%)/(5-1))*(J8-1) -> 0.07 | K15: =7%+((6%-7%)/(5-1))*(K8-1) -> 0.0675 | L15: =7%+((6%-7%)/(5-1))*(L8-1) -> 0.065 | M15: =7%+((6%-7%)/(5-1))*(M8-1) -> 0.0625 | N15: =7%+((6%-7%)/(5-1))*(N8-1) -> 0.06
J16: =J15-2% -> 0.05 | K16: =K15-2% -> 0.0475 | L16: =L15-2% -> 0.045 | M16: =M15-2% -> 0.0425 | N16: =N15-2% -> 0.04
A18: Total Material-Related Cost | B18: =SUM('Historical P&L'!B9:B11) -> -11383.46 | C18: =SUM('Historical P&L'!C9:C11) -> -12097.23 | D18: =SUM('Historical P&L'!D9:D11) -> -18300.75 | E18: =SUM('Historical P&L'!E9:E11) -> -21156.5 | F18: =SUM('Historical P&L'!F9:F11) -> -20090.21 | G18: =SUM('Historical P&L'!G9:G11) -> -19515.78 | H18: =SUM('Historical P&L'!H9:H11) -> -20001.78 | J18: =-J19*J11 -> -22117.819 | K18: =-K19*K11 -> -23610.772 | L18: =-L19*L11 -> -25145.472 | M18: =-M19*M11 -> -26717.064 | N18: =-N19*N11 -> -28320.088
A19: Percentage of Revenue (%) | B19: =-(B18/B11) -> 0.56322395 | C19: =-(C18/C11) -> 0.55714765 | D19: =-(D18/D11) -> 0.62886409 | E19: =-(E18/E11) -> 0.61343476 | F19: =-(F18/F11) -> 0.56600543 | G19: =-(G18/G11) -> 0.5755913 | H19: =-(H18/H11) -> 0.56210765 | J19: =CHOOSE($B$4,J21,J22,J23) -> 0.58091069 | K19: =CHOOSE($B$4,K21,K22,K23) -> 0.58091069 | L19: =CHOOSE($B$4,L21,L22,L23) -> 0.58091069 | M19: =CHOOSE($B$4,M21,M22,M23) -> 0.58091069 | N19: =CHOOSE($B$4,N21,N22,N23) -> 0.58091069
J21: 0.55 | K21: 0.55 | L21: 0.55 | M21: 0.55 | N21: 0.55
J22: =AVERAGE($B$19:$H$19) -> 0.58091069 | K22: =AVERAGE($B$19:$H$19) -> 0.58091069 | L22: =AVERAGE($B$19:$H$19) -> 0.58091069 | M22: =AVERAGE($B$19:$H$19) -> 0.58091069 | N22: =AVERAGE($B$19:$H$19) -> 0.58091069
J23: 0.63 | K23: 0.63 | L23: 0.63 | M23: 0.63 | N23: 0.63
A25: Employee Benefit Expenses | B25: ='Historical P&L'!B12 -> -1366.09 | C25: ='Historical P&L'!C12 -> -1540.75 | D25: ='Historical P&L'!D12 -> -1786.67 | E25: ='Historical P&L'!E12 -> -2028.07 | F25: ='Historical P&L'!F12 -> -2326.18 | G25: ='Historical P&L'!G12 -> -2597.23 | H25: ='Historical P&L'!H12 -> -2799.59 | J25: =-J26*J11 -> -2608.4451 | K25: =-K26*K11 -> -2784.5151 | L25: =-L26*L11 -> -2965.5086 | M25: =-M26*M11 -> -3150.8529 | N25: =-N26*N11 -> -3339.9041
A26: Percentage of Revenue (%) | B26: =-B25/B11 -> 0.067590575 | C26: =-C25/C11 -> 0.07096048 | D26: =-D25/D11 -> 0.061394894 | E26: =-E25/E11 -> 0.058804086 | F26: =-F25/F11 -> 0.065535926 | G26: =-G25/G11 -> 0.076601755 | H26: =-H25/H11 -> 0.078676545 | J26: =CHOOSE($B$4,J28,J29,J30) -> 0.06850918 | K26: =CHOOSE($B$4,K28,K29,K30) -> 0.06850918 | L26: =CHOOSE($B$4,L28,L29,L30) -> 0.06850918 | M26: =CHOOSE($B$4,M28,M29,M30) -> 0.06850918 | N26: =CHOOSE($B$4,N28,N29,N30) -> 0.06850918
J28: 0.055 | K28: 0.055 | L28: 0.055 | M28: 0.055 | N28: 0.055
J29: =AVERAGE($B$26:$H$26) -> 0.06850918 | K29: =AVERAGE($B$26:$H$26) -> 0.06850918 | L29: =AVERAGE($B$26:$H$26) -> 0.06850918 | M29: =AVERAGE($B$26:$H$26) -> 0.06850918 | N29: =AVERAGE($B$26:$H$26) -> 0.06850918
J30: 0.08 | K30: 0.08 | L30: 0.08 | M30: 0.08 | N30: 0.08
A32: Other Operating Expenses | B32: ='Historical P&L'!B13 -> -3299.93 | C32: ='Historical P&L'!C13 -> -3219.21 | D32: ='Historical P&L'!D13 -> -4210.25 | E32: ='Historical P&L'!E13 -> -5044.18 | F32: ='Historical P&L'!F13 -> -5493.36 | G32: ='Historical P&L'!G13 -> -5786.4 | H32: ='Historical P&L'!H13 -> -6086.25 | J32: =-J33*J11 -> -5977.3316 | K32: =-K33*K11 -> -6380.8014 | L32: =-L33*L11 -> -6795.5535 | M32: =-M33*M11 -> -7220.2756 | N32: =-N33*N11 -> -7653.4922
A33: Percentage of Revenue (%) | B33: =-B32/B11 -> 0.16327194 | C33: =-C32/C11 -> 0.1482633 | D33: =-D32/D11 -> 0.14467577 | E33: =-E32/E11 -> 0.14625649 | F33: =-F32/F11 -> 0.15476551 | G33: =-G32/G11 -> 0.17066197 | H33: =-H32/H11 -> 0.17104116 | J33: =CHOOSE($B$4,J35,J36,J37) -> 0.15699088 | K33: =CHOOSE($B$4,K35,K36,K37) -> 0.15699088 | L33: =CHOOSE($B$4,L35,L36,L37) -> 0.15699088 | M33: =CHOOSE($B$4,M35,M36,M37) -> 0.15699088 | N33: =CHOOSE($B$4,N35,N36,N37) -> 0.15699088
J35: 0.14 | K35: 0.14 | L35: 0.14 | M35: 0.14 | N35: 0.14
J36: =AVERAGE($B$33:$H$33) -> 0.15699088 | K36: =AVERAGE($B$33:$H$33) -> 0.15699088 | L36: =AVERAGE($B$33:$H$33) -> 0.15699088 | M36: =AVERAGE($B$33:$H$33) -> 0.15699088 | N36: =AVERAGE($B$33:$H$33) -> 0.15699088
J37: 0.175 | K37: 0.175 | L37: 0.175 | M37: 0.175 | N37: 0.175
A39: Capex | B39: ='Historical Cash Flow'!C6 -> -403.54 | C39: ='Historical Cash Flow'!D6 -> -281.87 | D39: ='Historical Cash Flow'!E6 -> -538.24 | E39: ='Historical Cash Flow'!F6 -> -1273.37 | F39: ='Historical Cash Flow'!G6 -> -2199.01 | G39: ='Historical Cash Flow'!H6 -> -1805.32 | H39: ='Historical Cash Flow'!I6 -> -1467.02 | J39: =-J40*J11 -> -1985.2757 | K39: =-K40*K11 -> -2119.2819 | L39: =-L40*L11 -> -2257.0352 | M39: =-M40*M11 -> -2398.0999 | N39: =-N40*N11 -> -2541.9859
A40: Percentage of Revenue (%) | B40: =-B39/B11 -> 0.019966108 | C40: =-C39/C11 -> 0.012981749 | D40: =-D39/D11 -> 0.018495406 | E40: =-E39/E11 -> 0.036921486 | F40: =-F39/F11 -> 0.061953141 | G40: =-G39/G11 -> 0.05324545 | H40: =-H39/H11 -> 0.041227489 | J40: =CHOOSE($B$4,J42,J43,J44) -> 0.052142027 | K40: =CHOOSE($B$4,K42,K43,K44) -> 0.052142027 | L40: =CHOOSE($B$4,L42,L43,L44) -> 0.052142027 | M40: =CHOOSE($B$4,M42,M43,M44) -> 0.052142027 | N40: =CHOOSE($B$4,N42,N43,N44) -> 0.052142027
B42: Latest % | D42: =H40 -> 0.041227489 | J42: =$D$42 -> 0.041227489 | K42: =$D$42 -> 0.041227489 | L42: =$D$42 -> 0.041227489 | M42: =$D$42 -> 0.041227489 | N42: =$D$42 -> 0.041227489
B43: 3 Year Average % | D43: =AVERAGE(F40:H40) -> 0.052142027 | J43: =$D$43 -> 0.052142027 | K43: =$D$43 -> 0.052142027 | L43: =$D$43 -> 0.052142027 | M43: =$D$43 -> 0.052142027 | N43: =$D$43 -> 0.052142027
B44: 7 Year Average % | D44: =AVERAGE(B40:H40) -> 0.034970119 | J44: =$D$44 -> 0.034970119 | K44: =$D$44 -> 0.034970119 | L44: =$D$44 -> 0.034970119 | M44: =$D$44 -> 0.034970119 | N44: =$D$44 -> 0.034970119
A46: Depreciation & Ammortization | B46: ='Historical P&L'!B16 -> -780.5 | C46: ='Historical P&L'!C16 -> -791.27 | D46: ='Historical P&L'!D16 -> -816.36 | E46: ='Historical P&L'!E16 -> -858.02 | F46: ='Historical P&L'!F16 -> -853 | G46: ='Historical P&L'!G16 -> -1026.34 | H46: ='Historical P&L'!H16 -> -1228.85
A47: Percentage of Revenue (%) | B47: =-B46/B11 -> 0.038617107 | C47: =-C46/C11 -> 0.036442576 | D47: =-D46/D11 -> 0.028052374 | E47: =-E46/E11 -> 0.024878373 | F47: =-F46/F11 -> 0.024031737 | G47: =-G46/G11 -> 0.030270498 | H47: =-H46/H11 -> 0.034534226
B49: Latest % | D49: =H47 -> 0.034534226
B50: 3 Year Average % | D50: =AVERAGE(F47:H47) -> 0.029612153
B51: 6 Year Average % | D51: =AVERAGE(B47:H47) -> 0.03097527
A53: Opening Net PP&E | B53: 5256.18 | C53: ='Historical BS'!C10 -> 4764.76 | D53: ='Historical BS'!D10 -> 4476.35 | E53: ='Historical BS'!E10 -> 4184.46 | F53: ='Historical BS'!F10 -> 4145.65 | G53: ='Historical BS'!G10 -> 4446.2 | H53: ='Historical BS'!H10 -> 6787.62 | J53: ='Historical BS'!I10 -> 7146.23 | O53: Column B FY19 opening balances are the comparative column of the FY2019-20 annual report.
A54: Opening ROU | B54: 0 | C54: ='Historical BS'!C12 -> 920.09 | D54: ='Historical BS'!D12 -> 845.55 | E54: ='Historical BS'!E12 -> 905.75 | F54: ='Historical BS'!F12 -> 1208.92 | G54: ='Historical BS'!G12 -> 1856.27 | H54: ='Historical BS'!H12 -> 1843.72 | J54: ='Historical BS'!I12 -> 2018.77
...

Sheet Forecast BS
A1: Balance Sheet Forecasted
A2: Units — ₹ Crores
A4: Years | B4: 2019-20 | C4: 2020-21 | D4: 2021-22 | E4: 2022-23 | F4: 2023-24 | G4: 2024-25 | H4: 2025-26 | J4: 2026-27 | K4: 2027-28 | L4: 2028-29 | M4: 2029-30 | N4: 2030-31 | O4: Comments
A5: Trade Recivables | B5: ='Historical BS'!C7 -> 1795.22 | C5: ='Historical BS'!D7 -> 2602.17 | D5: ='Historical BS'!E7 -> 3871.44 | E5: ='Historical BS'!F7 -> 4636.94 | F5: ='Historical BS'!G7 -> 4889.05 | G5: ='Historical BS'!H7 -> 4313.65 | H5: ='Historical BS'!I7 -> 4461.8 | J5: =(J6/365)*'Forecast P&L'!J11 -> 5009.3457 | K5: =(K6/365)*'Forecast P&L'!K11 -> 5347.4765 | L5: =(L6/365)*'Forecast P&L'!L11 -> 5695.0625 | M5: =(M6/365)*'Forecast P&L'!M11 -> 6051.0039 | N5: =(N6/365)*'Forecast P&L'!N11 -> 6414.0641
A6: DSO | B6: =(B5/'Forecast P&L'!B11)*365 -> 32.420325 | C6: =(C5/'Forecast P&L'!C11)*365 -> 43.743436 | D6: =(D5/'Forecast P&L'!D11)*365 -> 48.557163 | E6: =(E5/'Forecast P&L'!E11)*365 -> 49.073711 | F6: =(F5/'Forecast P&L'!F11)*365 -> 50.275161 | G6: =(G5/'Forecast P&L'!G11)*365 -> 46.437206 | H6: =(H5/'Forecast P&L'!H11)*365 -> 45.767144 | J6: =AVERAGE($D$6:$H$6) -> 48.022077 | K6: =AVERAGE($D$6:$H$6) -> 48.022077 | L6: =AVERAGE($D$6:$H$6) -> 48.022077 | M6: =AVERAGE($D$6:$H$6) -> 48.022077 | N6: =AVERAGE($D$6:$H$6) -> 48.022077 | O6: Average of the five years FY22-FY26, which sit in a narrow range
A8: Trade Payables | B8: ='Historical BS'!C13 -> 2136.57 | C8: ='Historical BS'!D13 -> 3378.72 | D8: ='Historical BS'!E13 -> 4164.3 | E8: ='Historical BS'!F13 -> 3635.44 | F8: ='Historical BS'!G13 -> 3831.34 | G8: ='Historical BS'!H13 -> 3848 | H8: ='Historical BS'!I13 -> 3863.04 | J8: =-(J9/365)*'Forecast P&L'!J18 -> 4283.5978 | K8: =-(K9/365)*'Forecast P&L'!K18 -> 4572.7407 | L8: =-(L9/365)*'Forecast P&L'!L18 -> 4869.9688 | M8: =-(M9/365)*'Forecast P&L'!M18 -> 5174.3419 | N8: =-(N9/365)*'Forecast P&L'!N18 -> 5484.8024
A9: DPO | B9: =-(B8/'Forecast P&L'!B18)*365 -> 68.507119 | C9: =-(C8/'Forecast P&L'!C18)*365 -> 101.9434 | D9: =-(D8/'Forecast P&L'!D18)*365 -> 83.055039 | E9: =-(E8/'Forecast P&L'!E18)*365 -> 62.719996 | F9: =-(F8/'Forecast P&L'!F18)*365 -> 69.607988 | G9: =-(G8/'Forecast P&L'!G18)*365 -> 71.968428 | H9: =-(H8/'Forecast P&L'!H18)*365 -> 70.494206 | J9: =AVERAGE($F$9:$H$9) -> 70.690207 | K9: =AVERAGE($F$9:$H$9) -> 70.690207 | L9: =AVERAGE($F$9:$H$9) -> 70.690207 | M9: =AVERAGE($F$9:$H$9) -> 70.690207 | N9: =AVERAGE($F$9:$H$9) -> 70.690207 | O9: Average of recent 3 years taken as they are close
A11: Inventories | B11: ='Historical BS'!C8 -> 3389.81 | C11: ='Historical BS'!D8 -> 3798.6 | D11: ='Historical BS'!E8 -> 6152.98 | E11: ='Historical BS'!F8 -> 6210.64 | F11: ='Historical BS'!G8 -> 5923.41 | G11: ='Historical BS'!H8 -> 6719.27 | H11: ='Historical BS'!I8 -> 5743.69 | J11: =-(J12/365)*'Forecast P&L'!J18 -> 6455.1343 | K11: =-(K12/365)*'Forecast P&L'!K18 -> 6890.8559 | L11: =-(L12/365)*'Forecast P&L'!L18 -> 7338.7615 | M11: =-(M12/365)*'Forecast P&L'!M18 -> 7797.4341 | N11: =-(N12/365)*'Forecast P&L'!N18 -> 8265.2802
A12: DIO | B12: =-(B11/'Forecast P&L'!B18)*365 -> 108.69109 | C12: =-(C11/'Forecast P&L'!C18)*365 -> 114.61211 | D12: =-(D11/'Forecast P&L'!D18)*365 -> 122.71834 | E12: =-(E11/'Forecast P&L'!E18)*365 -> 107.14833 | F12: =-(F11/'Forecast P&L'!F18)*365 -> 107.61683 | G12: =-(G11/'Forecast P&L'!G18)*365 -> 125.66926 | H12: =-(H11/'Forecast P&L'!H18)*365 -> 104.81301 | J12: =AVERAGE(H12,F12,E12) -> 106.52606 | K12: =$J$12 -> 106.52606 | L12: =$J$12 -> 106.52606 | M12: =$J$12 -> 106.52606 | N12: =$J$12 -> 106.52606 | O12: Average of FY23, FY24 and FY26; FY25 excluded as an outlier
A13: Net other operating working capital | B13: ='Historical BS'!C9-'Historical BS'!C14 -> -1282.82 | C13: ='Historical BS'!D9-'Historical BS'!D14 -> -1379.8 | D13: ='Historical BS'!E9-'Historical BS'!E14 -> -1791.35 | E13: ='Historical BS'!F9-'Historical BS'!F14 -> -2415.29 | F13: ='Historical BS'!G9-'Historical BS'!G14 -> -2436.57 | G13: ='Historical BS'!H9-'Historical BS'!H14 -> -2486.06 | H13: ='Historical BS'!I9-'Historical BS'!I14 -> -2922.65 | J13: ='Forecast P&L'!J11*AVERAGE($F$13/'Forecast P&L'!$F$11,$G$13/'Forecast P&L'!$G$11,$H$13/'Forecast P&L'!$H$11) -> -2844.205 | K13: ='Forecast P&L'!K11*AVERAGE($F$13/'Forecast P&L'!$F$11,$G$13/'Forecast P&L'!$G$11,$H$13/'Forecast P&L'!$H$11) -> -3036.1888 | L13: ='Forecast P&L'!L11*AVERAGE($F$13/'Forecast P&L'!$F$11,$G$13/'Forecast P&L'!$G$11,$H$13/'Forecast P&L'!$H$11) -> -3233.5411 | M13: ='Forecast P&L'!M11*AVERAGE($F$13/'Forecast P&L'!$F$11,$G$13/'Forecast P&L'!$G$11,$H$13/'Forecast P&L'!$H$11) -> -3435.6374 | N13: ='Forecast P&L'!N11*AVERAGE($F$13/'Forecast P&L'!$F$11,$G$13/'Forecast P&L'!$G$11,$H$13/'Forecast P&L'!$H$11) -> -3641.7757 | O13: Other current assets less other current liabilities/provisions; forecast using latest 3-year average as % of revenue
A14: Working Capital | B14: =B5+B11+B13-B8 -> 1765.64 | C14: =C5+C11+C13-C8 -> 1642.25 | D14: =D5+D11+D13-D8 -> 4068.77 | E14: =E5+E11+E13-E8 -> 4796.85 | F14: =F5+F11+F13-F8 -> 4544.55 | G14: =G5+G11+G13-G8 -> 4698.86 | H14: =H5+H11+H13-H8 -> 3419.8 | J14: =J5+J11+J13-J8 -> 4336.6772 | K14: =K5+K11+K13-K8 -> 4629.4029 | L14: =L5+L11+L13-L8 -> 4930.3141 | M14: =M5+M11+M13-M8 -> 5238.4587 | N14: =N5+N11+N13-N8 -> 5552.7663 | O14: Working capital now matches Historical BS scope: AR + inventory + net other operating WC - trade payables
A15: Change In Working Capital | C15: =C14-B14 -> -123.39 | D15: =D14-C14 -> 2426.52 | E15: =E14-D14 -> 728.08 | F15: =F14-E14 -> -252.3 | G15: =G14-F14 -> 154.31 | H15: =H14-G14 -> -1279.06 | J15: =J14-H14 -> 916.87721 | K15: =K14-J14 -> 292.72571 | L15: =L14-K14 -> 300.91119 | M15: =M14-L14 -> 308.14463 | N15: =N14-M14 -> 314.30752

Sheet Forecast FCF
A1: Cash Flow Forecasted
A2: Units — ₹ Crores
A4: Years | B4: 2019-20 | C4: 2020-21 | D4: 2021-22 | E4: 2022-23 | F4: 2023-24 | G4: 2024-25 | H4: 2025-26 | J4: 2026-27 | K4: 2027-28 | L4: 2028-29 | M4: 2029-30 | N4: 2030-31 | O4: Comments
A5: NOPAT | B5: ='Forecast P&L'!B88 -> 2585.8692 | C5: ='Forecast P&L'!C88 -> 3027.9346 | D5: ='Forecast P&L'!D88 -> 2937.1373 | E5: ='Forecast P&L'!E88 -> 3983.6693 | F5: ='Forecast P&L'!F88 -> 5091.9201 | G5: ='Forecast P&L'!G88 -> 3620.149 | H5: ='Forecast P&L'!H88 -> 4002.0518 | J5: ='Forecast P&L'!J88 -> 4471.1914 | K5: ='Forecast P&L'!K88 -> 4773.1551 | L5: ='Forecast P&L'!L88 -> 5081.1256 | M5: ='Forecast P&L'!M88 -> 5394.1224 | N5: ='Forecast P&L'!N88 -> 5711.0309
A6: Add: Depreciation & Ammortization | B6: =-'Forecast P&L'!B59 -> 780.5 | C6: =-'Forecast P&L'!C59 -> 791.27 | D6: =-'Forecast P&L'!D59 -> 816.36 | E6: =-'Forecast P&L'!E59 -> 858.02 | F6: =-'Forecast P&L'!F59 -> 853 | G6: =-'Forecast P&L'!G59 -> 1026.34 | H6: =-'Forecast P&L'!H59 -> 1228.85 | J6: =-'Forecast P&L'!J59 -> 1350.9871 | K6: =-'Forecast P&L'!K59 -> 1441.9657 | L6: =-'Forecast P&L'!L59 -> 1538.7693 | M6: =-'Forecast P&L'!M59 -> 1641.1001 | N6: =-'Forecast P&L'!N59 -> 1748.6388
A7: Gross Cash Flow | B7: =SUM(B5:B6) -> 3366.3692 | C7: =SUM(C5:C6) -> 3819.2046 | D7: =SUM(D5:D6) -> 3753.4973 | E7: =SUM(E5:E6) -> 4841.6893 | F7: =SUM(F5:F6) -> 5944.9201 | G7: =SUM(G5:G6) -> 4646.489 | H7: =SUM(H5:H6) -> 5230.9018 | J7: =SUM(J5:J6) -> 5822.1785 | K7: =SUM(K5:K6) -> 6215.1208 | L7: =SUM(L5:L6) -> 6619.8949 | M7: =SUM(M5:M6) -> 7035.2224 | N7: =SUM(N5:N6) -> 7459.6698
A8: Less: Capex | B8: ='Forecast P&L'!B39 -> -403.54 | C8: ='Forecast P&L'!C39 -> -281.87 | D8: ='Forecast P&L'!D39 -> -538.24 | E8: ='Forecast P&L'!E39 -> -1273.37 | F8: ='Forecast P&L'!F39 -> -2199.01 | G8: ='Forecast P&L'!G39 -> -1805.32 | H8: ='Forecast P&L'!H39 -> -1467.02 | J8: ='Forecast P&L'!J39 -> -1985.2757 | K8: ='Forecast P&L'!K39 -> -2119.2819 | L8: ='Forecast P&L'!L39 -> -2257.0352 | M8: ='Forecast P&L'!M39 -> -2398.0999 | N8: ='Forecast P&L'!N39 -> -2541.9859
A9: Less: Investment in right-of-use assets | B9: ='Historical Cash Flow'!C8 -> -10.15 | C9: ='Historical Cash Flow'!D8 -> -6.84 | D9: ='Historical Cash Flow'!E8 -> -12.46 | E9: ='Historical Cash Flow'!F8 -> -172.24 | F9: ='Historical Cash Flow'!G8 -> -297.07 | G9: ='Historical Cash Flow'!H8 -> -24.75 | H9: ='Historical Cash Flow'!I8 -> -20.3 | J9: =AVERAGE($F$9/'Forecast P&L'!$F$11,$G$9/'Forecast P&L'!$G$11,$H$9/'Forecast P&L'!$H$11)*'Forecast P&L'!J11 -> -122.72476 | K9: =AVERAGE($F$9/'Forecast P&L'!$F$11,$G$9/'Forecast P&L'!$G$11,$H$9/'Forecast P&L'!$H$11)*'Forecast P&L'!K11 -> -131.00868 | L9: =AVERAGE($F$9/'Forecast P&L'!$F$11,$G$9/'Forecast P&L'!$G$11,$H$9/'Forecast P&L'!$H$11)*'Forecast P&L'!L11 -> -139.52425 | M9: =AVERAGE($F$9/'Forecast P&L'!$F$11,$G$9/'Forecast P&L'!$G$11,$H$9/'Forecast P&L'!$H$11)*'Forecast P&L'!M11 -> -148.24451 | N9: =AVERAGE($F$9/'Forecast P&L'!$F$11,$G$9/'Forecast P&L'!$G$11,$H$9/'Forecast P&L'!$H$11)*'Forecast P&L'!N11 -> -157.13918 | O9: Cash paid to acquire right-of-use assets, per the consolidated cash flow statement, forecast on the latest three-year average as a percentage of revenue. Charged against free cash flow so that lease investment is captured, consistent with lease liabilities being deducted as debt in the equity bridge.
A10: Less: Investment In Working Capital | C10: ='Forecast BS'!C15 -> -123.39 | D10: ='Forecast BS'!D15 -> 2426.52 | E10: ='Forecast BS'!E15 -> 728.08 | F10: ='Forecast BS'!F15 -> -252.3 | G10: ='Forecast BS'!G15 -> 154.31 | H10: ='Forecast BS'!H15 -> -1279.06 | J10: ='Forecast BS'!J15 -> 916.87721 | K10: ='Forecast BS'!K15 -> 292.72571 | L10: ='Forecast BS'!L15 -> 300.91119 | M10: ='Forecast BS'!M15 -> 308.14463 | N10: ='Forecast BS'!N15 -> 314.30752
A11: Net Cash Flow | B11: =SUM(B7:B9)-B10 -> 2952.6792 | C11: =SUM(C7:C9)-C10 -> 3653.8846 | D11: =SUM(D7:D9)-D10 -> 776.27731 | E11: =SUM(E7:E9)-E10 -> 2667.9993 | F11: =SUM(F7:F9)-F10 -> 3701.1401 | G11: =SUM(G7:G9)-G10 -> 2662.109 | H11: =SUM(H7:H9)-H10 -> 5022.6418 | J11: =SUM(J7:J9)-J10 -> 2797.3008 | K11: =SUM(K7:K9)-K10 -> 3672.1045 | L11: =SUM(L7:L9)-L10 -> 3922.4243 | M11: =SUM(M7:M9)-M10 -> 4180.7334 | N11: =SUM(N7:N9)-N10 -> 4446.2372

Sheet WACC
A1: WACC & BETA Calculation
A2: Units — ₹ Crores
A4: WACC CALCULATIONS | E4: BETA CALCULATION CHART | O4: BETA | P4: BSE500 | Q4: =SLOPE(G8:G91,I8:I91) -> 0.68460935
A5: Header | B5: Amount | C5: Comments | E5: Date | F5: Asian Paints | H5: BSE500 | J5: NSE500 | L5: NSE50 | P5: NSE500 | Q5: =SLOPE(G8:G91,K8:K91) -> 0.68026568
A6: Total Equity to Capital | B6: =IF(B25=1,B31/(B31+B33),IF(B25=2,B32/(B32+B33),"Invalid Input")) -> 0.98142762 | F6: Price | G6: Growth Rate (%) | H6: Price | I6: Growth Rate (%) | J6: Price | K6: Growth Rate (%) | L6: Price | M6: Growth Rate (%) | P6: NSE50 | Q6: =SLOPE(G8:G91,M8:M91) -> 0.73433289
A7: Total Debt to Capital | B7: =IF(B25=1,B33/(B31+B33),IF(B25=2,B33/(B33+B32),"Invalid Input")) -> 0.01857238 | E7: 43556 | F7: 1463.15 | H7: 15293.75 | J7: 9664.3 | L7: 11748.15
A8: Calculations | E8: 43586 | F8: 1407.3 | G8: =F8/F7-1 -> -0.038171069 | H8: 15517.9 | I8: =H8/H7-1 -> 0.014656314 | J8: 9805.05 | K8: =J8/J7-1 -> 0.01456391 | L8: 11922.8 | M8: =L8/L7-1 -> 0.01486617
E9: 43617 | F9: 1358.15 | G9: =F9/F8-1 -> -0.034925034 | H9: 15291.7 | I9: =H9/H8-1 -> -0.014576715 | J9: 9657.95 | K9: =J9/J8-1 -> -0.015002473 | L9: 11788.85 | M9: =L9/L8-1 -> -0.011234777
A10: Risk free Rate | B10: 0.07106 | C10: https://tradingeconomics.com/india/government-bond-yield | E10: 43647 | F10: 1521.1 | G10: =F10/F9-1 -> 0.11997938 | H10: 14324.12 | I10: =H10/H9-1 -> -0.063274848 | J10: 9044.95 | K10: =J10/J9-1 -> -0.063471026 | L10: 11118 | M10: =L10/L9-1 -> -0.056905466
A11: Equity Beta | B11: 0.7 | C11: BSE 500 & NSE 500 are a better gauge as we are comparing to more number of companies for beta, however nifty 50 also does compare many high ranked companies in the NSE, so we will incline more towards 6.8 but not exactly | E11: 43678 | F11: 1616.2 | G11: =F11/F10-1 -> 0.062520544 | H11: 14234.07 | I11: =H11/H10-1 -> -0.0062865991 | J11: 8977.55 | K11: =J11/J10-1 -> -0.0074516719 | L11: 11023.25 | M11: =L11/L10-1 -> -0.0085222162
A12: Market Risk Premium | B12: 0.069 | C12: https://papers.ssrn.com/sol3/papers.cfm?abstract_id=6570342 | E12: 43709 | F12: 1762.15 | G12: =F12/F11-1 -> 0.090304418 | H12: 14810.02 | I12: =H12/H11-1 -> 0.040462777 | J12: 9340.9 | K12: =J12/J11-1 -> 0.04047318 | L12: 11474.45 | M12: =L12/L11-1 -> 0.040931667
A13: Cost of Equity | B13: =B10+B11*B12 -> 0.11936 | E13: 43739 | F13: 1809.6 | G13: =F13/F12-1 -> 0.026927333 | H13: 15387.13 | I13: =H13/H12-1 -> 0.038967537 | J13: 9689.65 | K13: =J13/J12-1 -> 0.037335803 | L13: 11877.45 | M13: =L13/L12-1 -> 0.035121509
E14: 43770 | F14: 1706.15 | G14: =F14/F13-1 -> -0.05716733 | H14: 15567.67 | I14: =H14/H13-1 -> 0.011733182 | J14: 9813.65 | K14: =J14/J13-1 -> 0.01279716 | L14: 12056.05 | M14: =L14/L13-1 -> 0.015036898
A15: Credit Spread | B15: 0.006 | C15: https://www.crisil.com/mnt/winshare/Ratings/RatingList/RatingDocs/AsianPaintsLimited_September%2010_%202025_RR_376066.html | E15: 43800 | F15: 1784.95 | G15: =F15/F14-1 -> 0.046185857 | H15: 15667.44 | I15: =H15/H14-1 -> 0.0064087946 | J15: 9872.55 | K15: =J15/J14-1 -> 0.0060018444 | L15: 12168.45 | M15: =L15/L14-1 -> 0.0093231199
A16: Pre-Tax Cost of Debt | B16: =B10+B15 -> 0.07706 | E16: 43831 | F16: 1795.65 | G16: =F16/F15-1 -> 0.0059945657 | H16: 15649.81 | I16: =H16/H15-1 -> -0.0011252636 | J16: 9861.45 | K16: =J16/J15-1 -> -0.0011243296 | L16: 11962.1 | M16: =L16/L15-1 -> -0.016957788
A17: Maringal Tax rate | B17: 0.2517 | C17: For an Indian domestic company under Section 115BAA, the base tax rate is 22%. The Income Tax Department also states that for companies under Section 115BAA, surcharge is 10%, and Health & Education Cess is 4%. | E17: 43862 | F17: 1797.95 | G17: =F17/F16-1 -> 0.0012808732 | H17: 14627.62 | I17: =H17/H16-1 -> -0.065316448 | J17: 9236.05 | K17: =J17/J16-1 -> -0.063418666 | L17: 11201.75 | M17: =L17/L16-1 -> -0.063563254
A18: Cost of Debt | B18: =B16*(1-B17) -> 0.057663998 | E18: 43891 | F18: 1666.5 | G18: =F18/F17-1 -> -0.073111043 | H18: 11098.23 | I18: =H18/H17-1 -> -0.24128259 | J18: 6996.75 | K18: =J18/J17-1 -> -0.24245213 | L18: 8597.75 | M18: =L18/L17-1 -> -0.23246368
E19: 43922 | F19: 1758.7 | G19: =F19/F18-1 -> 0.055325533 | H19: 12721 | I19: =H19/H18-1 -> 0.14621881 | J19: 8012.9 | K19: =J19/J18-1 -> 0.14523171 | L19: 9859.9 | M19: =L19/L18-1 -> 0.14680003
A20: Weight Average Cost of Equity | B20: =B13*B6 -> 0.1171432 | E20: 43952 | F20: 1683.1 | G20: =F20/F19-1 -> -0.042986297 | H20: 12414.85 | I20: =H20/H19-1 -> -0.024066504 | J20: 7822.4 | K20: =J20/J19-1 -> -0.023774164 | L20: 9580.3 | M20: =L20/L19-1 -> -0.028357286
A21: Weighted Average Cost of Debt | B21: =B18*B7 -> 0.0010709577 | E21: 43983 | F21: 1687.45 | G21: =F21/F20-1 -> 0.0025845167 | H21: 13438.14 | I21: =H21/H20-1 -> 0.082424677 | J21: 8474.8 | K21: =J21/J20-1 -> 0.083401514 | L21: 10302.1 | M21: =L21/L20-1 -> 0.075342108
E22: 44013 | F22: 1715.5 | G22: =F22/F21-1 -> 0.016622715 | H22: 14346.18 | I22: =H22/H21-1 -> 0.067571851 | J22: 9035.75 | K22: =J22/J21-1 -> 0.066190353 | L22: 11073.45 | M22: =L22/L21-1 -> 0.074873084
A23: Weighted Average Cost of Capital | B23: =B20+B21 -> 0.11821416 | E23: 44044 | F23: 1899.1 | G23: =F23/F22-1 -> 0.10702419 | H23: 14890.06 | I23: =H23/H22-1 -> 0.037911137 | J23: 9372.05 | K23: =J23/J22-1 -> 0.037218825 | L23: 11387.5 | M23: =L23/L22-1 -> 0.028360628
E24: 44075 | F24: 1986.4 | G24: =F24/F23-1 -> 0.045969143 | H24: 14851 | I24: =H24/H23-1 -> -0.0026232265 | J24: 9341.75 | K24: =J24/J23-1 -> -0.0032330173 | L24: 11247.55 | M24: =L24/L23-1 -> -0.012289791
A25: Equity Value Case Selector | B25: 2 | E25: 44105 | F25: 2211.5 | G25: =F25/F24-1 -> 0.11332058 | H25: 15215.01 | I25: =H25/H24-1 -> 0.024510807 | J25: 9581.65 | K25: =J25/J24-1 -> 0.025680413 | L25: 11642.4 | M25: =L25/L24-1 -> 0.035105423
A26: 1 = Calculation based Total Equity Value | E26: 44136 | F26: 2215.3 | G26: =F26/F25-1 -> 0.0017182908 | H26: 16995.01 | I26: =H26/H25-1 -> 0.11698974 | J26: 10719.05 | K26: =J26/J25-1 -> 0.11870607 | L26: 12968.95 | M26: =L26/L25-1 -> 0.11394128
A27: 2 = Annual Report based Total Equity Value | E27: 44166 | F27: 2764.5 | G27: =F27/F26-1 -> 0.24791225 | H27: 18300.1 | I27: =H27/H26-1 -> 0.076792541 | J27: 11518.3 | K27: =J27/J26-1 -> 0.074563511 | L27: 13981.75 | M27: =L27/L26-1 -> 0.078094217
E28: 44197 | F28: 2407.35 | G28: =F28/F27-1 -> -0.12919154 | H28: 17975.3 | I28: =H28/H27-1 -> -0.017748537 | J28: 11302.4 | K28: =J28/J27-1 -> -0.018744085 | L28: 13634.6 | M28: =L28/L27-1 -> -0.024828795
A29: Shares Outstanding | B29: 95.919779 | E29: 44228 | F29: 2277.2 | G29: =F29/F28-1 -> -0.054063597 | H29: 19371.25 | I29: =H29/H28-1 -> 0.077659344 | J29: 12181.4 | K29: =J29/J28-1 -> 0.077771093 | L29: 14529.15 | M29: =L29/L28-1 -> 0.065608819
A30: Price Per Share | B30: 2164.5 | E30: 44256 | F30: 2537.4 | G30: =F30/F29-1 -> 0.11426313 | H30: 19601.95 | I30: =H30/H29-1 -> 0.011909402 | J30: 12313.7 | K30: =J30/J29-1 -> 0.010860821 | L30: 14690.7 | M30: =L30/L29-1 -> 0.011119026
A31: Total Equity Value | B31: =B29*B30 -> 207618.36 | E31: 44287 | F31: 2536.4 | G31: =F31/F30-1 -> -0.0003941042 | H31: 19689.52 | I31: =H31/H30-1 -> 0.0044674127 | J31: 12364.35 | K31: =J31/J30-1 -> 0.0041133047 | L31: 14631.1 | M31: =L31/L30-1 -> -0.0040569884
A32: Total Equity Value (2025-26 Annual Report) | B32: 207618 | E32: 44317 | F32: 2977.5 | G32: =F32/F31-1 -> 0.1739079 | H32: 21055.18 | I32: =H32/H31-1 -> 0.069359741 | J32: 13226.35 | K32: =J32/J31-1 -> 0.069716564 | L32: 15582.8 | M32: =L32/L31-1 -> 0.065046374
A33: Total Debt Value | B33: ='Historical BS'!I15+'Historical BS'!I17+'Historical BS'!I18 -> 3928.93 | E33: 44348 | F33: 2992.7 | G33: =F33/F32-1 -> 0.0051049538 | H33: 21463.09 | I33: =H33/H32-1 -> 0.01937338 | J33: 13473.55 | K33: =J33/J32-1 -> 0.018689964 | L33: 15721.5 | M33: =L33/L32-1 -> 0.0089008394
E34: 44378 | F34: 2958.45 | G34: =F34/F33-1 -> -0.011444515 | H34: 21753.68 | I34: =H34/H33-1 -> 0.013539057 | J34: 13664.25 | K34: =J34/J33-1 -> 0.014153657 | L34: 15763.05 | M34: =L34/L33-1 -> 0.0026428776
E35: 44409 | F35: 3201.35 | G35: =F35/F34-1 -> 0.082103804 | H35: 23174.23 | I35: =H35/H34-1 -> 0.065301595 | J35: 14555.9 | K35: =J35/J34-1 -> 0.065254222 | L35: 17132.2 | M35: =L35/L34-1 -> 0.086858191
E36: 44440 | F36: 3244.65 | G36: =F36/F35-1 -> 0.013525544 | H36: 23937.54 | I36: =H36/H35-1 -> 0.03293788 | J36: 15052.65 | K36: =J36/J35-1 -> 0.034127055 | L36: 17618.15 | M36: =L36/L35-1 -> 0.028364717
E37: 44470 | F37: 3100.1 | G37: =F37/F36-1 -> -0.04455026 | H37: 23990.09 | I37: =H37/H36-1 -> 0.0021952966 | J37: 15086.9 | K37: =J37/J36-1 -> 0.0022753469 | L37: 17671.65 | M37: =L37/L36-1 -> 0.0030366412
E38: 44501 | F38: 3143.65 | G38: =F38/F37-1 -> 0.014047934 | H38: 23276.88 | I38: =H38/H37-1 -> -0.029729359 | J38: 14648.35 | K38: =J38/J37-1 -> -0.029068265 | L38: 16983.2 | M38: =L38/L37-1 -> -0.038957879
E39: 44531 | F39: 3382.95 | G39: =F39/F38-1 -> 0.076121706 | H39: 23811 | I39: =H39/H38-1 -> 0.022946374 | J39: 14996.2 | K39: =J39/J38-1 -> 0.023746702 | L39: 17354.05 | M39: =L39/L38-1 -> 0.021836285
E40: 44562 | F40: 3152.25 | G40: =F40/F39-1 -> -0.068194919 | H40: 23715.29 | I40: =H40/H39-1 -> -0.0040195708 | J40: 14921.45 | K40: =J40/J39-1 -> -0.0049845961 | L40: 17339.85 | M40: =L40/L39-1 -> -0.0008182528
E41: 44593 | F41: 3174.65 | G41: =F41/F40-1 -> 0.0071060354 | H41: 22741.64 | I41: =H41/H40-1 -> -0.041055791 | J41: 14307.95 | K41: =J41/J40-1 -> -0.041115307 | L41: 16793.9 | M41: =L41/L40-1 -> -0.031485278
...

Sheet DCF
A1: Discounted Cash Flow
A2: Units — ₹ Crores
A4: WACC | B4: =WACC!B23 -> 0.11821416
A5: Terminal Growth Rate Selector | B5: 2 | O5: Terminal Growth Rate Options | P5: Pessimistic | Q5: 0.01
P6: Base | Q6: 0.02
P7: Optimistic | Q7: 0.03
A9: Years | B9: 2019-20 | C9: 2020-21 | D9: 2021-22 | E9: 2022-23 | F9: 2023-24 | G9: 2024-25 | H9: 2025-26 | J9: 2026-27 | K9: 2027-28 | L9: 2028-29 | M9: 2029-30 | N9: 2030-31 | O9: Comments
A10: Net Cash Flow | C10: ='Forecast FCF'!C11 -> 3653.8846 | D10: ='Forecast FCF'!D11 -> 776.27731 | E10: ='Forecast FCF'!E11 -> 2667.9993 | F10: ='Forecast FCF'!F11 -> 3701.1401 | G10: ='Forecast FCF'!G11 -> 2662.109 | H10: ='Forecast FCF'!H11 -> 5022.6418 | J10: ='Forecast FCF'!J11 -> 2797.3008 | K10: ='Forecast FCF'!K11 -> 3672.1045 | L10: ='Forecast FCF'!L11 -> 3922.4243 | M10: ='Forecast FCF'!M11 -> 4180.7334 | N10: ='Forecast FCF'!N11 -> 4446.2372
A11: Discounting Factor | J11: =1/(1+Sensitivity!$L$5)^1 -> 0.89428308 | K11: =1/(1+Sensitivity!$L$5)^2 -> 0.79974222 | L11: =1/(1+Sensitivity!$L$5)^3 -> 0.71519594 | M11: =1/(1+Sensitivity!$L$5)^4 -> 0.63958763 | N11: =1/(1+Sensitivity!$L$5)^5 -> 0.57197239
J12: =J10*J11 -> 2501.5788 | K12: =K10*K11 -> 2936.7371 | L12: =L10*L11 -> 2805.3019 | M12: =M10*M11 -> 2673.9454 | N12: =N10*N11 -> 2543.1249
A16: DCF Value | B16: =SUM(J12:N12) -> 13460.688 | C16: =B16/B20 -> 0.33759556
A17: Chosen Terminal Growth Rate | B17: =Sensitivity!L6 -> 0.02
A18: Continuing Value | B18: =(N10*(1+Sensitivity!L6))/(Sensitivity!L5-Sensitivity!L6) -> 46176.254
A19: Present Value of Continuing Value | B19: =B18*N11 -> 26411.542 | C19: =B19/B20 -> 0.66240444
A20: Enterprise Value | B20: =B19+B16 -> 39872.231
A23: Add: Cash & Cash Equivalents | B23: ='Historical BS'!I5 -> 672.83
A24: Add: Other balances with banks | B24: ='Historical BS'!I23 -> 400.85
A25: Add: Current Investments | B25: ='Historical BS'!I6 -> 6285.83
A26: Less: Short-term borrowings | B26: ='Historical BS'!I15 -> 1046.09
A27: Less: Long-term borrowings | B27: ='Historical BS'!I17 -> 1247.17
A28: Less: Lease liabilities | B28: ='Historical BS'!I18 -> 1635.67
A29: Less: Non-controlling interest / NCI | B29: ='Historical BS'!I22 -> 643.39
A30: Equity Value | B30: =B20+B23+B24+B25-SUM(B26:B29) -> 42659.421
A31: Number of Shares | B31: 95.919779
A32: Price Per Equity Share | B32: =B30/B31 -> 444.7406
A34: Reconciliation to Market Price
A35: Market price per share (INR) | B35: =WACC!$B$30 -> 2164.5
A36: Shares outstanding (crore) | B36: =B31 -> 95.919779
A37: Market capitalisation | B37: =B35*B36 -> 207618.36
A38: Add: Short-term borrowings | B38: =B26 -> 1046.09
A39: Add: Long-term borrowings | B39: =B27 -> 1247.17
A40: Add: Lease liabilities | B40: =B28 -> 1635.67
A41: Add: Non-controlling interest | B41: =B29 -> 643.39
A42: Less: Cash, bank balances and current investments | B42: =-(B23+B24+B25) -> -7359.51
A43: Market-implied Enterprise Value | B43: =SUM(B37:B42) -> 204831.17
A44: Less: PV of explicit forecast cash flow | B44: =-B16 -> -13460.688
A45: Market-implied PV of continuing value | B45: =B43+B44 -> 191370.48
A46: Market-implied continuing value at FY31 | B46: =B45/N11 -> 334579.93
A47: Market-implied terminal growth rate | B47: =(B46*B4-N10)/(B46+N10) -> 0.10354908
A48: Terminal growth rate used in this model | B48: =B17 -> 0.02
...

Sheet Sensitivity
A1: Sensitivity Analysis
A2: Units — ₹ Crores
B4: Enterprise Value | C4: Terminal Growth Rate (%)
B5: WACC (%) | C5: =DCF!B20 -> 39872.231 | D5: 0.01 | E5: 0.02 | F5: 0.03 | G5: 0.04 | H5: 0.05 | I5: 0.06 | K5: Weighted Average Cost of Capital (%) | L5: =WACC!B23 -> 0.11821416
C6: =WACC!$B$23-0.02 -> 0.098214158 | D6: 46077.537 | E6: 50507.711 | F6: 56236.787 | G6: 63934.139 | H6: 74824.474 | I6: 91414.444 | K6: Terminal Growth Rate (%) | L6: =CHOOSE(DCF!B5,DCF!Q5,DCF!Q6,DCF!Q7) -> 0.02
C7: =WACC!$B$23-0.01 -> 0.10821416 | D7: 41181.822 | E7: 44584.223 | F7: 48856.645 | G7: 54381.717 | H7: 61804.978 | I7: 72307.525
C8: =WACC!$B$23 -> 0.11821416 | D8: 37196.549 | E8: 39872.231 | F8: 43154.546 | G8: 47276.176 | H8: 52606.244 | I8: 59767.506
C9: =WACC!$B$23+0.01 -> 0.12821416 | D9: 33890.448 | E9: 36035.673 | F9: 38617.745 | G9: 41785.226 | H9: 45762.658 | I9: 50906.25
C10: =WACC!$B$23+0.02 -> 0.13821416 | D10: 31104.414 | E10: 32852.212 | F10: 34923.036 | G10: 37415.555 | H10: 40473.181 | I10: 44312.666
C11: =WACC!$B$23+0.03 -> 0.14821416 | D11: 28725.397 | E11: 30168.882 | F11: 31856.584 | G11: 33856.204 | H11: 36263.019 | I11: 39215.511
B14: Per Share Price | C14: Terminal Growth Rate (%)
B15: WACC (%) | C15: =DCF!B32 -> 444.7406 | D15: 0.01 | E15: 0.02 | F15: 0.03 | G15: 0.04 | H15: 0.05 | I15: 0.06
C16: =WACC!$B$23-0.02 -> 0.098214158 | D16: 509.43328 | E16: 555.61952 | F16: 615.3473 | G16: 695.59511 | H16: 809.13097 | I16: 982.08768
C17: =WACC!$B$23-0.01 -> 0.10821416 | D17: 458.39359 | E17: 493.86491 | F17: 538.40653 | G17: 596.0075 | H17: 673.3978 | I17: 782.89082
C18: =WACC!$B$23 -> 0.11821416 | D18: 416.84561 | E18: 444.7406 | F18: 478.95998 | G18: 521.92954 | H18: 577.49752 | I18: 652.15638
C19: =WACC!$B$23+0.01 -> 0.12821416 | D19: 382.37826 | E19: 404.74304 | F19: 431.66211 | G19: 464.68431 | H19: 506.15054 | I19: 559.77444
C20: =WACC!$B$23+0.02 -> 0.13821416 | D20: 353.3328 | E20: 371.55426 | F20: 393.14338 | G20: 419.12883 | H20: 451.00574 | I20: 491.03383
C21: =WACC!$B$23+0.03 -> 0.14821416 | D21: 328.53064 | E21: 343.57953 | F21: 361.17445 | G21: 382.02125 | H21: 407.11321 | I21: 437.89405

Sheet Summary
A1: Sensitivity Analysis
A3: Formatting Legend
A4: Formula / calculation cells | B4: Light grey fill | C4: Used for model calculations and linked formulas
A5: Key output / essential information | B5: Light blue fill | C5: Used for final valuation outputs and important subtotal rows
A6: Scenario case areas | B6: Lavender fill | C6: Used for optimistic / base / pessimistic scenario blocks
A7: Case selectors | B7: Yellow fill | C7: Used for any cell which needs to be interacted with to select a case
A8: Headings | B8: Orange fill | C8: Used for the headings of any table which depict what data is in the table
A10: Enterprise Value to Equity Value Bridge | G10: Key Valuation Assumptions
A11: Item | B11: Value | C11: Unit | D11: Source / Formula | E11: Comment | G11: Assumption | H11: Value | I11: Source | J11: Comment
A12: Enterprise Value | B12: =DCF!$B$20 -> 39872.231 | C12: ₹ cr | D12: DCF!B20 | E12: Present value of forecast FCF + terminal value | G12: Selected case | H12: =CHOOSE('Forecast P&L'!$B$4,"Bullish","Base","Bearish") -> Base | I12: Forecast P&L!B4 | J12: 1 = Bullish, 2 = Base, 3 = Bearish
A13: Add: Cash and cash equivalents | B13: =DCF!$B$23 -> 672.83 | C13: ₹ cr | D13: DCF!B23 | E13: Cash-like asset added back | G13: WACC | H13: =DCF!$B$4 -> 0.11821416 | I13: DCF!B4 | J13: Discount rate used in DCF
A14: Add: Other balances with banks | B14: =DCF!$B$24 -> 400.85 | C14: ₹ cr | D14: DCF!B24 | E14: Cash-like bank balance added back | G14: Terminal growth rate | H14: =DCF!$B$17 -> 0.02 | I14: DCF!B17 | J14: Growth rate used for terminal value
A15: Add: Current investments | B15: =DCF!$B$25 -> 6285.83 | C15: ₹ cr | D15: DCF!B25 | E15: Marketable/current financial investments added back | G15: Risk-free rate | H15: =WACC!$B$10 -> 0.07106 | I15: WACC!B10 | J15: India government bond yield input
A16: Less: Short-term borrowings | B16: =-DCF!$B$26 -> -1046.09 | C16: ₹ cr | D16: DCF!B26 | E16: Debt-like claim deducted | G16: Equity beta | H16: =WACC!$B$11 -> 0.7 | I16: WACC!B11 | J16: Selected beta assumption
A17: Less: Long-term borrowings | B17: =-DCF!$B$27 -> -1247.17 | C17: ₹ cr | D17: DCF!B27 | E17: Debt-like claim deducted | G17: Market risk premium | H17: =WACC!$B$12 -> 0.069 | I17: WACC!B12 | J17: Equity risk premium assumption
A18: Less: Lease liabilities | B18: =-DCF!$B$28 -> -1635.67 | C18: ₹ cr | D18: DCF!B28 | E18: Lease obligations treated as debt-like | G18: Cost of equity | H18: =WACC!$B$13 -> 0.11936 | I18: WACC!B13 | J18: Rf + beta × MRP
A19: Less: Non-controlling interest / NCI | B19: =-DCF!$B$29 -> -643.39 | C19: ₹ cr | D19: DCF!B29 | E19: Value belonging to minority shareholders deducted | G19: Pre-tax cost of debt | H19: =WACC!$B$16 -> 0.07706 | I19: WACC!B16 | J19: Risk-free rate + credit spread
A20: Equity Value | B20: =DCF!$B$30 -> 42659.421 | C20: ₹ cr | D20: DCF!B30 | E20: Value attributable to ordinary shareholders | G20: Marginal tax rate | H20: =WACC!$B$17 -> 0.2517 | I20: WACC!B17 | J20: Tax shield assumption
A21: Shares Outstanding | B21: =DCF!$B$31 -> 95.919779 | C21: cr shares | D21: DCF!B31 | E21: Used for value per share | G21: Forecast revenue CAGR | H21: =('Forecast P&L'!$N$11/'Forecast P&L'!$H$11)^(1/5)-1 -> 0.064994131 | I21: Forecast P&L | J21: FY26 actual to FY31 forecast CAGR
A22: Intrinsic Value per Share | B22: =DCF!$B$32 -> 444.7406 | C22: ₹ / share | D22: DCF!B32 | E22: DCF equity value divided by shares | G22: Final year EBITDA margin | H22: ='Forecast P&L'!$N$83/'Forecast P&L'!$N$78 -> 0.19358925 | I22: Forecast P&L | J22: FY31 EBITDA / FY31 revenue
A23: Market-implied price (Annual Report market cap) | B23: =WACC!$B$32/WACC!$B$29 -> 2164.4962 | C23: ₹ / share | D23: WACC!B32 / WACC!B29 | E23: Company-reported market cap divided by shares | G23: Final year EBIT margin | H23: ='Forecast P&L'!$N$85/'Forecast P&L'!$N$78 -> 0.15772061 | I23: Forecast P&L | J23: FY31 EBIT / FY31 revenue
A24: Upside / (Downside) vs annual report price | B24: =B22/B23-1 -> -0.79452928 | C24: % | D24: Intrinsic / market-implied price - 1 | E24: Valuation gap | G24: Final year FCF margin | H24: ='Forecast FCF'!$N$11/'Forecast P&L'!$N$78 -> 0.091202638 | I24: Forecast FCF | J24: FY31 FCF / FY31 revenue
A27: Forecast Summary | H27: DCF Value Breakdown
A28: Item | B28: ='Forecast P&L'!J9 -> 2026-27 | C28: ='Forecast P&L'!K9 -> 2027-28 | D28: ='Forecast P&L'!L9 -> 2028-29 | E28: ='Forecast P&L'!M9 -> 2029-30 | F28: ='Forecast P&L'!N9 -> 2030-31 | H28: Item | I28: Value | J28: % of EV
A29: Revenue | B29: ='Forecast P&L'!J11 -> 38074.388 | C29: ='Forecast P&L'!K11 -> 40644.409 | D29: ='Forecast P&L'!L11 -> 43286.296 | E29: ='Forecast P&L'!M11 -> 45991.689 | F29: ='Forecast P&L'!N11 -> 48751.19 | H29: PV of Explicit Forecast FCF | I29: =DCF!$B$16 -> 13460.688 | J29: =I29/I32 -> 0.33759556
A30: Revenue Growth | B30: ='Forecast P&L'!J12 -> 0.07 | C30: ='Forecast P&L'!K12 -> 0.0675 | D30: ='Forecast P&L'!L12 -> 0.065 | E30: ='Forecast P&L'!M12 -> 0.0625 | F30: ='Forecast P&L'!N12 -> 0.06 | H30: Terminal Value | I30: =DCF!$B$18 -> 46176.254
A31: EBITDA | B31: ='Forecast P&L'!J83 -> 7370.7922 | C31: ='Forecast P&L'!K83 -> 7868.3207 | D31: ='Forecast P&L'!L83 -> 8379.7615 | E31: ='Forecast P&L'!M83 -> 8903.4966 | F31: ='Forecast P&L'!N83 -> 9437.7064 | H31: PV of Terminal Value | I31: =DCF!$B$19 -> 26411.542 | J31: =I31/I32 -> 0.66240444
A32: EBITDA Margin | B32: =B31/B29 -> 0.19358925 | C32: =C31/C29 -> 0.19358925 | D32: =D31/D29 -> 0.19358925 | E32: =E31/E29 -> 0.19358925 | F32: =F31/F29 -> 0.19358925 | H32: Enterprise Value | I32: =DCF!$B$20 -> 39872.231 | J32: =I32/I32 -> 1
A33: EBIT | B33: ='Forecast P&L'!J85 -> 6019.8051 | C33: ='Forecast P&L'!K85 -> 6426.355 | D33: ='Forecast P&L'!L85 -> 6840.9923 | E33: ='Forecast P&L'!M85 -> 7262.3966 | F33: ='Forecast P&L'!N85 -> 7689.0676
A34: EBIT Margin | B34: =B33/B29 -> 0.15810642 | C34: =C33/C29 -> 0.15811166 | D34: =D33/D29 -> 0.1580406 | E34: =E33/E29 -> 0.15790672 | F34: =F33/F29 -> 0.15772061
A35: NOPAT | B35: ='Forecast P&L'!J88 -> 4471.1914 | C35: ='Forecast P&L'!K88 -> 4773.1551 | D35: ='Forecast P&L'!L88 -> 5081.1256 | E35: ='Forecast P&L'!M88 -> 5394.1224 | F35: ='Forecast P&L'!N88 -> 5711.0309
A36: Free Cash Flow | B36: ='Forecast FCF'!J11 -> 2797.3008 | C36: ='Forecast FCF'!K11 -> 3672.1045 | D36: ='Forecast FCF'!L11 -> 3922.4243 | E36: ='Forecast FCF'!M11 -> 4180.7334 | F36: ='Forecast FCF'!N11 -> 4446.2372
A37: FCF Margin | B37: =B36/B29 -> 0.073469358 | C37: =C36/C29 -> 0.090347101 | D37: =D36/D29 -> 0.090615846 | E37: =E36/E29 -> 0.090901932 | F37: =F36/F29 -> 0.091202638
A40: Per Share Sensitivity: WACC vs Terminal Growth
A41: =Sensitivity!B14 -> Per Share Price | B41: =Sensitivity!C14 -> Terminal Growth Rate (%)
A42: =Sensitivity!B15 -> WACC (%) | B42: =Sensitivity!C15 -> 444.7406 | C42: =Sensitivity!D15 -> 0.01 | D42: =Sensitivity!E15 -> 0.02 | E42: =Sensitivity!F15 -> 0.03 | F42: =Sensitivity!G15 -> 0.04 | G42: =Sensitivity!H15 -> 0.05 | H42: =Sensitivity!I15 -> 0.06
B43: =Sensitivity!C16 -> 0.098214158 | C43: =Sensitivity!D16 -> 509.43328 | D43: =Sensitivity!E16 -> 555.61952 | E43: =Sensitivity!F16 -> 615.3473 | F43: =Sensitivity!G16 -> 695.59511 | G43: =Sensitivity!H16 -> 809.13097 | H43: =Sensitivity!I16 -> 982.08768
B44: =Sensitivity!C17 -> 0.10821416 | C44: =Sensitivity!D17 -> 458.39359 | D44: =Sensitivity!E17 -> 493.86491 | E44: =Sensitivity!F17 -> 538.40653 | F44: =Sensitivity!G17 -> 596.0075 | G44: =Sensitivity!H17 -> 673.3978 | H44: =Sensitivity!I17 -> 782.89082
B45: =Sensitivity!C18 -> 0.11821416 | C45: =Sensitivity!D18 -> 416.84561 | D45: =Sensitivity!E18 -> 444.7406 | E45: =Sensitivity!F18 -> 478.95998 | F45: =Sensitivity!G18 -> 521.92954 | G45: =Sensitivity!H18 -> 577.49752 | H45: =Sensitivity!I18 -> 652.15638
B46: =Sensitivity!C19 -> 0.12821416 | C46: =Sensitivity!D19 -> 382.37826 | D46: =Sensitivity!E19 -> 404.74304 | E46: =Sensitivity!F19 -> 431.66211 | F46: =Sensitivity!G19 -> 464.68431 | G46: =Sensitivity!H19 -> 506.15054 | H46: =Sensitivity!I19 -> 559.77444
...

Sheet Decision Log
A1: Decision Log — Historical BS and Cash Flow Build
A3: Area | B3: Item | C3: Treatment used | D3: What was included | E3: What was excluded / fallback | F3: Why
A4: Scope | B4: Financial statements used | C4: Consolidated statements | D4: Used consolidated balance sheet and consolidated cash flow statements from uploaded Asian Paints annual reports. | E4: Standalone statements | F4: Market cap values the group, so consolidated statements are the better base for DCF unless the model is explicitly standalone.
A5: Units | B5: All figures | C5: ₹ crores | D5: All annual reports present the relevant consolidated financial statements in ₹ crores. | E5: No conversion to ₹ millions in this workbook | F5: Maintains consistency with the P&L already entered in the workbook.
A6: Balance sheet | B6: Trade receivables | C6: Current trade receivables only | D6: Used current trade receivables for DSO and operating working capital. | E6: Non-current trade receivables | F6: Non-current receivables are not a normal revenue-cycle driver and are immaterial for DSO.
A7: Balance sheet | B7: Other current assets | C7: Operating current assets only | D7: Used the direct 'Other Current Assets' line. | E7: Cash, current investments, other financial assets, tax assets | F7: Those are financial/non-operating or tax items rather than normal operating working capital drivers.
A8: Balance sheet | B8: Current investments | C8: Separate non-operating asset | D8: Kept current investments separately for cash/net debt or equity bridge work. | E8: Not included in operating working capital | F8: Investment income should not be capitalised in operating FCF and then added back again.
A9: Balance sheet | B9: Intangible assets | C9: Other Intangible Assets only | D9: Used the Other Intangible Assets line only, as the depreciable base should exclude goodwill. | E9: Goodwill; investments in associates | F9: Goodwill is not depreciated and associates are separate non-operating strategic investments, so neither belongs in the depreciable asset base.
A10: Balance sheet | B10: Trade payables | C10: MSME + other creditors | D10: Added both disclosed trade payable sub-lines. | E10: Borrowings, lease liabilities, tax liabilities | F10: Only supplier payables belong in DPO / operating working capital.
A11: Balance sheet | B11: Other current liabilities | C11: Other financial liabilities + other current liabilities + provisions | D11: Combined these as a broad operating-current-liability bucket. | E11: Borrowings, current lease liabilities, income tax liabilities | F11: The CFS treats other financial liabilities, other liabilities and provisions as working-capital movements; debt and tax are handled separately.
A12: Balance sheet | B12: Current maturities of long-term debt | C12: Left as zero / not separately disclosed | D12: The main consolidated BS does not separately show current maturities; it shows one current borrowings line. | E12: No manual split from notes | F12: Avoids inventing a split not clearly required for the model at this stage.
A13: Balance sheet | B13: Lease liabilities | C13: Current + non-current lease liabilities | D13: Added both lease liability lines as debt-like items. | E13: Lease repayment not included in unlevered FCF | F13: Lease liabilities are debt-like for the equity bridge, but unlevered FCF is before financing.
