Workbook

Sheet Cover Page
A1: Nestlé India Limited (NSE: NESTLEIND)
A2: Valuation date: 31 December 2018
A3: All figures in ₹ million
A4: Share price used: ₹11,107
A5: Method: unlevered DCF, five-year forecast plus terminal value
A6: Prepared by: Neev Hiranandani

Sheet 1.Input -->
B11: 1.Input -->

Sheet P&L assumptions
B1: P&L assumptions
G2: Possible Cases | I2: Optimistic | J2: 1
I3: Average | J3: 2
B4: Selected case | C4: 2 | I4: Pessimistic | J4: 3
B6: INR in Millions | C6: FY14 Actual | D6: FY15 Actual | E6: FY16 Actual | F6: FY17 Actual | G6: FY18 Actual | I6: FY19 Forecast | J6: FY20 Forecast | K6: FY21 Forecast | L6: FY22 Forecast | M6: FY23 Forecast
B7: Net Revenue | C7: ='P&L Source'!C9 -> 98548.4 | D7: ='P&L Source'!D9 -> 81753.1 | E7: ='P&L Source'!E9 -> 91413.4 | F7: ='P&L Source'!F9 -> 100096 | G7: ='P&L Source'!G9 -> 112922.7 | I7: =G7*(I8+1) -> 124211.58 | J7: =I7*(J8+1) -> 136629.01 | K7: =J7*(K8+1) -> 150287.82 | L7: =K7*(L8+1) -> 165312.09 | M7: =L7*(M8+1) -> 181838.34
B8: Growth Rate (%) | D8: =D7/C7-1 -> -0.17042692 | E8: =E7/D7-1 -> 0.11816433 | F8: =F7/E7-1 -> 0.094981699 | G8: =G7/F7-1 -> 0.12814398 | I8: =CHOOSE($C$4,I10,I11,I12) -> 0.09997 | J8: =CHOOSE($C$4,J10,J11,J12) -> 0.09997 | K8: =CHOOSE($C$4,K10,K11,K12) -> 0.09997 | L8: =CHOOSE($C$4,L10,L11,L12) -> 0.09997 | M8: =CHOOSE($C$4,M10,M11,M12) -> 0.09997
I10: 0.12 | J10: 0.12 | K10: 0.12 | L10: 0.12 | M10: 0.12
I11: 0.09997 | J11: 0.09997 | K11: 0.09997 | L11: 0.09997 | M11: 0.09997
I12: 0.05 | J12: 0.05 | K12: 0.05 | L12: 0.05 | M12: 0.05
B14: Cost of Materials Consumed | C14: ='P&L Source'!C11 -> -45239.6 | D14: ='P&L Source'!D11 -> -34689.1 | E14: ='P&L Source'!E11 -> -38828.1 | F14: ='P&L Source'!F11 -> -43268 | G14: ='P&L Source'!G11 -> -45902.3 | I14: =-(I$7*I15) -> -52293.076 | J14: =-(J$7*J15) -> -57520.815 | K14: =-(K$7*K15) -> -63271.171 | L14: =-(L$7*L15) -> -69596.39 | M14: =-(M$7*M15) -> -76553.941
B15: % of Net Revenue | C15: =-(C14/C7) -> 0.45905971 | D15: =-(D14/D7) -> 0.42431541 | E15: =-(E14/E7) -> 0.42475283 | F15: =-(F14/F7) -> 0.43226503 | G15: =-(G14/G7) -> 0.40649311 | I15: =CHOOSE($C$4,I17,I18,I19) -> 0.421 | J15: =CHOOSE($C$4,J17,J18,J19) -> 0.421 | K15: =CHOOSE($C$4,K17,K18,K19) -> 0.421 | L15: =CHOOSE($C$4,L17,L18,L19) -> 0.421 | M15: =CHOOSE($C$4,M17,M18,M19) -> 0.421
I17: 0.41 | J17: 0.41 | K17: 0.41 | L17: 0.41 | M17: 0.41
I18: 0.421 | J18: 0.421 | K18: 0.421 | L18: 0.421 | M18: 0.421
I19: 0.45 | J19: 0.45 | K19: 0.45 | L19: 0.45 | M19: 0.45
B21: Marketing & Other Operating Expenses | C21: ='P&L Source'!C12 -> -31926.8 | D21: ='P&L Source'!D12 -> -29971.7 | E21: ='P&L Source'!E12 -> -33655 | F21: ='P&L Source'!F12 -> -35221.2 | G21: ='P&L Source'!G12 -> -40459.4 | I21: =-(I$7*I22) -> -43138.683 | J21: =-(J$7*J22) -> -47451.257 | K21: =-(K$7*K22) -> -52194.959 | L21: =-(L$7*L22) -> -57412.889 | M21: =-(M$7*M22) -> -63152.455
B22: % of Net Revenue | C22: =-(C21/C7) -> 0.32397076 | D22: =-(D21/D7) -> 0.3666124 | E22: =-(E21/E7) -> 0.36816265 | F22: =-(F21/F7) -> 0.3518742 | G22: =-(G21/G7) -> 0.35829289 | I22: =CHOOSE($C$4,I24,I25,I26) -> 0.3473 | J22: =CHOOSE($C$4,J24,J25,J26) -> 0.3473 | K22: =CHOOSE($C$4,K24,K25,K26) -> 0.3473 | L22: =CHOOSE($C$4,L24,L25,L26) -> 0.3473 | M22: =CHOOSE($C$4,M24,M25,M26) -> 0.3473
I24: 0.32 | J24: 0.32 | K24: 0.32 | L24: 0.32 | M24: 0.32
I25: 0.3473 | J25: 0.3473 | K25: 0.3473 | L25: 0.3473 | M25: 0.3473
I26: 0.36 | J26: 0.36 | K26: 0.36 | L26: 0.36 | M26: 0.36
B28: Depreciation & Ammortization Expenses | C28: ='P&L Source'!C15 -> -3375.4 | D28: ='P&L Source'!D15 -> -3472.6 | E28: ='P&L Source'!E15 -> -3536.7 | F28: ='P&L Source'!F15 -> -3422.5 | G28: ='P&L Source'!G15 -> -3356.7 | I28: =-(I$7*I29) -> -4367.2792 | J28: =-(J$7*J29) -> -4803.8761 | K28: =-(K$7*K29) -> -5284.1196 | L28: =-(L$7*L29) -> -5812.3731 | M28: =-(M$7*M29) -> -6393.436
B29: % of Net Revenue | C29: =-(C28/C7) -> 0.03425119 | D29: =-(D28/D7) -> 0.042476677 | E29: =-(E28/E7) -> 0.038689076 | F29: =-(F28/F7) -> 0.034192176 | G29: =-(G28/G7) -> 0.029725644 | I29: =CHOOSE($C$4,I31,I32,I33) -> 0.03516 | J29: =CHOOSE($C$4,J31,J32,J33) -> 0.03516 | K29: =CHOOSE($C$4,K31,K32,K33) -> 0.03516 | L29: =CHOOSE($C$4,L31,L32,L33) -> 0.03516 | M29: =CHOOSE($C$4,M31,M32,M33) -> 0.03516
I31: 0.029 | J31: 0.029 | K31: 0.029 | L31: 0.029 | M31: 0.029
I32: 0.03516 | J32: 0.03516 | K32: 0.03516 | L32: 0.03516 | M32: 0.03516
I33: 0.042 | J33: 0.042 | K33: 0.042 | L33: 0.042 | M33: 0.042
B35: Tax Expense (%) | C35: -0.33232451 | D35: -0.30770743 | E35: -0.35202992 | F35: -0.33387156 | G35: -0.33842607 | I35: =CHOOSE($C$4,I38,I39,I40) -> -0.3 | J35: =CHOOSE($C$4,J38,J39,J40) -> -0.3 | K35: =CHOOSE($C$4,K38,K39,K40) -> -0.3 | L35: =CHOOSE($C$4,L38,L39,L40) -> -0.3 | M35: =CHOOSE($C$4,M38,M39,M40) -> -0.3
I38: -0.25 | J38: -0.25 | K38: -0.25 | L38: -0.25 | M38: -0.25
I39: -0.3 | J39: -0.3 | K39: -0.3 | L39: -0.3 | M39: -0.3
I40: -0.35 | J40: -0.35 | K40: -0.35 | L40: -0.35 | M40: -0.35

Sheet BS assumptions
B1: BS assumptions
B3: INR in Millions | C3: FY14 Actual | D3: FY15 Actual | E3: FY16 Actual | F3: FY17 Actual | G3: FY18 Actual | H3: FY19 Forecast | I3: FY20 Forecast | J3: FY21 Forecast | K3: FY22 Forecast | L3: FY23 Forecast
B4: Accounts Receivable | C4: ='BS Source'!C18 -> 991 | D4: ='BS Source'!D18 -> 784.2 | E4: ='BS Source'!E18 -> 979.3 | F4: ='BS Source'!F18 -> 889.7 | G4: ='BS Source'!G18 -> 1245.9 | H4: =(H5/365)*'P&L assumptions'!I7 -> 1249.1417 | I4: =(I5/365)*'P&L assumptions'!J7 -> 1374.0184 | J4: =(J5/365)*'P&L assumptions'!K7 -> 1511.379 | K4: =(K5/365)*'P&L assumptions'!L7 -> 1662.4716 | L4: =(L5/365)*'P&L assumptions'!M7 -> 1828.6689
B5: DSO | C5: =(C4/'P&L Source'!C9)*365 -> 3.67043 | D5: =(D4/'P&L Source'!D9)*365 -> 3.5011883 | E5: =(E4/'P&L Source'!E9)*365 -> 3.9101981 | F5: =(F4/'P&L Source'!F9)*365 -> 3.2442905 | G5: =(G4/'P&L Source'!G9)*365 -> 4.0271221 | H5: =AVERAGE($C$5:$G$5) -> 3.6706458 | I5: =AVERAGE($C$5:$G$5) -> 3.6706458 | J5: =AVERAGE($C$5:$G$5) -> 3.6706458 | K5: =AVERAGE($C$5:$G$5) -> 3.6706458 | L5: =AVERAGE($C$5:$G$5) -> 3.6706458
B7: Accounts Payable | C7: ='BS Source'!C38 -> 7287.1 | D7: ='BS Source'!D38 -> 7494.1 | E7: ='BS Source'!E38 -> 7991.6 | F7: ='BS Source'!F38 -> 9846.4 | G7: ='BS Source'!G38 -> 12403.7 | H7: =-(H8/365)*'P&L assumptions'!I14 -> 11302.849 | I7: =-(I8/365)*'P&L assumptions'!J14 -> 12432.795 | J7: =-(J8/365)*'P&L assumptions'!K14 -> 13675.701 | K7: =-(K8/365)*'P&L assumptions'!L14 -> 15042.861 | L7: =-(L8/365)*'P&L assumptions'!M14 -> 16546.696
B8: DPO | C8: =-(C7/'P&L Source'!C11)*365 -> 58.793435 | D8: =-(D7/'P&L Source'!D11)*365 -> 78.853199 | E8: =-(E7/'P&L Source'!E11)*365 -> 75.124304 | F8: =-(F7/'P&L Source'!F11)*365 -> 83.062217 | G8: =-(G7/'P&L Source'!G11)*365 -> 98.630145 | H8: =AVERAGE($C$8:$G$8) -> 78.89266 | I8: =AVERAGE($C$8:$G$8) -> 78.89266 | J8: =AVERAGE($C$8:$G$8) -> 78.89266 | K8: =AVERAGE($C$8:$G$8) -> 78.89266 | L8: =AVERAGE($C$8:$G$8) -> 78.89266
B10: Inventory | C10: ='BS Source'!C17 -> 8441 | D10: ='BS Source'!D17 -> 8208.1 | E10: ='BS Source'!E17 -> 9400.6 | F10: ='BS Source'!F17 -> 9024.7 | G10: ='BS Source'!G17 -> 9655.5 | H10: =-(H11/365)*'P&L assumptions'!I14 -> 11339.62 | I10: =-(I11/365)*'P&L assumptions'!J14 -> 12473.241 | J10: =-(J11/365)*'P&L assumptions'!K14 -> 13720.191 | K10: =-(K11/365)*'P&L assumptions'!L14 -> 15091.799 | L10: =-(L11/365)*'P&L assumptions'!M14 -> 16600.526
B11: DIO | C11: =-(C10/'P&L Source'!C11)*365 -> 68.103277 | D11: =-(D10/'P&L Source'!D11)*365 -> 86.365933 | E11: =-(E10/'P&L Source'!E11)*365 -> 88.36948 | F11: =-(F10/'P&L Source'!F11)*365 -> 76.130524 | G11: =-(G10/'P&L Source'!G11)*365 -> 76.777362 | H11: =AVERAGE($C$11:$G$11) -> 79.149315 | I11: =AVERAGE($C$11:$G$11) -> 79.149315 | J11: =AVERAGE($C$11:$G$11) -> 79.149315 | K11: =AVERAGE($C$11:$G$11) -> 79.149315 | L11: =AVERAGE($C$11:$G$11) -> 79.149315
B13: Net PP&E (closing) | C13: ='BS Source'!C8 -> 34214.2 | D13: ='BS Source'!D8 -> 31286.4 | E13: ='BS Source'!E8 -> 29183.1 | F13: ='BS Source'!F8 -> 27103.4 | G13: ='BS Source'!G8 -> 25058.2 | H13: =G13+H14+'P&L assumptions'!I28 -> 23175.152 | I13: =H13+I14+'P&L assumptions'!J28 -> 22128.574 | J13: =I13+J14+'P&L assumptions'!K28 -> 22128.574 | K13: =J13+K14+'P&L assumptions'!L28 -> 22128.574 | L13: =K13+L14+'P&L assumptions'!M28 -> 22128.574
B14: Capex | D14: =BS!D6 -> 544.8 | E14: =BS!E6 -> 1433.4 | F14: =BS!F6 -> 1342.8 | G14: =BS!G6 -> 1311.5 | H14: =H15*'P&L assumptions'!I7 -> 2484.2316 | I14: =I15*'P&L assumptions'!J7 -> 3757.2979 | J14: =J15*'P&L assumptions'!K7 -> 5284.1196 | K14: =K15*'P&L assumptions'!L7 -> 5812.3731 | L14: =L15*'P&L assumptions'!M7 -> 6393.436
B15: Capex (% of Net Revenue) | D15: =D14/'P&L Source'!D9 -> 0.0066639675 | E15: =E14/'P&L Source'!E9 -> 0.015680414 | F15: =F14/'P&L Source'!F9 -> 0.013415121 | G15: =G14/'P&L Source'!G9 -> 0.01161414 | H15: =CHOOSE('P&L assumptions'!$C$4,'BS assumptions'!H16,'BS assumptions'!H17,'BS assumptions'!H18) -> 0.02 | I15: =CHOOSE('P&L assumptions'!$C$4,'BS assumptions'!I16,'BS assumptions'!I17,'BS assumptions'!I18) -> 0.0275 | J15: =CHOOSE('P&L assumptions'!$C$4,'BS assumptions'!J16,'BS assumptions'!J17,'BS assumptions'!J18) -> 0.03516 | K15: =CHOOSE('P&L assumptions'!$C$4,'BS assumptions'!K16,'BS assumptions'!K17,'BS assumptions'!K18) -> 0.03516 | L15: =CHOOSE('P&L assumptions'!$C$4,'BS assumptions'!L16,'BS assumptions'!L17,'BS assumptions'!L18) -> 0.03516 | N15: Capex forecast directly as a percentage of sales. FY15-18 capex averaged only 1.18% of sales, equal to 0.4x depreciation, which drew Net PP&E down from 34,214 to 25,058 and cannot continue indefinitely. The average case therefore ramps capex to maintenance level, defined as equal to the depreciation ratio, by FY21 and holds it there.
B16: Optimistic | H16: 0.015 | I16: 0.02 | J16: 0.025 | K16: 0.0275 | L16: 0.03
B17: Average | H17: 0.02 | I17: 0.0275 | J17: ='P&L assumptions'!K29 -> 0.03516 | K17: ='P&L assumptions'!L29 -> 0.03516 | L17: ='P&L assumptions'!M29 -> 0.03516
B18: Pessimistic | H18: 0.025 | I18: 0.035 | J18: 0.04 | K18: 0.0425 | L18: 0.045
B20: Memo: Capex / Depreciation (x) | D20: =-D14/'P&L assumptions'!D28 -> 0.15688533 | E20: =-E14/'P&L assumptions'!E28 -> 0.40529307 | F20: =-F14/'P&L assumptions'!F28 -> 0.39234478 | G20: =-G14/'P&L assumptions'!G28 -> 0.39071112 | H20: =-H14/'P&L assumptions'!I28 -> 0.56882821 | I20: =-I14/'P&L assumptions'!J28 -> 0.78213879 | J20: =-J14/'P&L assumptions'!K28 -> 1 | K20: =-K14/'P&L assumptions'!L28 -> 1 | L20: =-L14/'P&L assumptions'!M28 -> 1
B21: Memo: Net PP&E (% of Net Revenue) | D21: =D13/'P&L Source'!D9 -> 0.38269374 | E21: =E13/'P&L Source'!E9 -> 0.31924313 | F21: =F13/'P&L Source'!F9 -> 0.27077406 | G21: =G13/'P&L Source'!G9 -> 0.22190578 | H21: =H13/'P&L assumptions'!I7 -> 0.18657803 | I21: =I13/'P&L assumptions'!J7 -> 0.16196102 | J21: =J13/'P&L assumptions'!K7 -> 0.1472413 | K21: =K13/'P&L assumptions'!L7 -> 0.13385938 | L21: =L13/'P&L assumptions'!M7 -> 0.12169367
B22: Memo: Implied depreciation rate on opening Net PP&E | D22: =-'P&L assumptions'!D28/C13 -> 0.10149587 | E22: =-'P&L assumptions'!E28/D13 -> 0.11304273 | F22: =-'P&L assumptions'!F28/E13 -> 0.11727678 | G22: =-'P&L assumptions'!G28/F13 -> 0.12384793 | H22: =-'P&L assumptions'!I28/G13 -> 0.17428543 | I22: =-'P&L assumptions'!J28/H13 -> 0.20728563 | J22: =-'P&L assumptions'!K28/I13 -> 0.23879169 | K22: =-'P&L assumptions'!L28/J13 -> 0.2626637 | L22: =-'P&L assumptions'!M28/K13 -> 0.28892219

Sheet 2.Output-->
B11: 2.Output -->

Sheet P&L
B1: P&L
B3: INR in Millions | C3: FY14 Actual | D3: FY15 Actual | E3: FY16 Actual | F3: FY17 Actual | G3: FY18 Actual | H3: FY19 Forecast | I3: FY20 Forecast | J3: FY21 Forecast | K3: FY22 Forecast | L3: FY23 Forecast | N3: Note
B4: Revenues | C4: ='P&L assumptions'!C7 -> 98548.4 | D4: ='P&L assumptions'!D7 -> 81753.1 | E4: ='P&L assumptions'!E7 -> 91413.4 | F4: ='P&L assumptions'!F7 -> 100096 | G4: ='P&L assumptions'!G7 -> 112922.7 | H4: ='P&L assumptions'!I7 -> 124211.58 | I4: ='P&L assumptions'!J7 -> 136629.01 | J4: ='P&L assumptions'!K7 -> 150287.82 | K4: ='P&L assumptions'!L7 -> 165312.09 | L4: ='P&L assumptions'!M7 -> 181838.34
B5: Cost of goods sold | C5: ='P&L assumptions'!C14 -> -45239.6 | D5: ='P&L assumptions'!D14 -> -34689.1 | E5: ='P&L assumptions'!E14 -> -38828.1 | F5: ='P&L assumptions'!F14 -> -43268 | G5: ='P&L assumptions'!G14 -> -45902.3 | H5: ='P&L assumptions'!I14 -> -52293.076 | I5: ='P&L assumptions'!J14 -> -57520.815 | J5: ='P&L assumptions'!K14 -> -63271.171 | K5: ='P&L assumptions'!L14 -> -69596.39 | L5: ='P&L assumptions'!M14 -> -76553.941
B6: Gross Margin | C6: =ABS(-(C5/C4)-1) -> 0.54094029 | D6: =ABS(-(D5/D4)-1) -> 0.57568459 | E6: =ABS(-(E5/E4)-1) -> 0.57524717 | F6: =ABS(-(F5/F4)-1) -> 0.56773497 | G6: =ABS(-(G5/G4)-1) -> 0.59350689 | H6: =ABS(-(H5/H4)-1) -> 0.579 | I6: =ABS(-(I5/I4)-1) -> 0.579 | J6: =ABS(-(J5/J4)-1) -> 0.579 | ... L6: =ABS(-(L5/L4)-1) -> 0.579
B7: ='P&L assumptions'!B21 -> Marketing & Other Operating Expenses | C7: ='P&L assumptions'!C21 -> -31926.8 | D7: ='P&L assumptions'!D21 -> -29971.7 | E7: ='P&L assumptions'!E21 -> -33655 | F7: ='P&L assumptions'!F21 -> -35221.2 | G7: ='P&L assumptions'!G21 -> -40459.4 | H7: ='P&L assumptions'!I21 -> -43138.683 | I7: ='P&L assumptions'!J21 -> -47451.257 | J7: ='P&L assumptions'!K21 -> -52194.959 | K7: ='P&L assumptions'!L21 -> -57412.889 | L7: ='P&L assumptions'!M21 -> -63152.455
B8: EBITDA | C8: =SUM(C4:C5)+C7 -> 21382 | D8: =SUM(D4:D5)+D7 -> 17092.3 | E8: =SUM(E4:E5)+E7 -> 18930.3 | F8: =SUM(F4:F5)+F7 -> 21606.8 | G8: =SUM(G4:G5)+G7 -> 26561 | H8: =SUM(H4:H5)+H7 -> 28779.824 | I8: =SUM(I4:I5)+I7 -> 31656.943 | J8: =SUM(J4:J5)+J7 -> 34821.687 | ... L8: =SUM(L4:L5)+L7 -> 42131.943
B9: D&A | C9: ='P&L assumptions'!C28 -> -3375.4 | D9: ='P&L assumptions'!D28 -> -3472.6 | E9: ='P&L assumptions'!E28 -> -3536.7 | F9: ='P&L assumptions'!F28 -> -3422.5 | G9: ='P&L assumptions'!G28 -> -3356.7 | H9: ='P&L assumptions'!I28 -> -4367.2792 | I9: ='P&L assumptions'!J28 -> -4803.8761 | J9: ='P&L assumptions'!K28 -> -5284.1196 | K9: ='P&L assumptions'!L28 -> -5812.3731 | L9: ='P&L assumptions'!M28 -> -6393.436
B10: EBIT | C10: =SUM(C8:C9) -> 18006.6 | D10: =SUM(D8:D9) -> 13619.7 | E10: =SUM(E8:E9) -> 15393.6 | F10: =SUM(F8:F9) -> 18184.3 | G10: =SUM(G8:G9) -> 23204.3 | H10: =SUM(H8:H9) -> 24412.544 | I10: =SUM(I8:I9) -> 26853.066 | J10: =SUM(J8:J9) -> 29537.568 | ... L10: =SUM(L8:L9) -> 35738.507
B11: Taxes | C11: =C12*C10 -> -5984.0346 | D11: =D12*D10 -> -4190.8829 | E11: =E12*E10 -> -5419.0078 | F11: =F12*F10 -> -6071.2207 | G11: =G12*G10 -> -7852.94 | H11: =H12*H10 -> -7323.7633 | I11: =I12*I10 -> -8055.9199 | J11: =J12*J10 -> -8861.2703 | ... L11: =L12*L10 -> -10721.552
B12: Tax rate | C12: ='P&L assumptions'!C35 -> -0.33232451 | D12: ='P&L assumptions'!D35 -> -0.30770743 | E12: ='P&L assumptions'!E35 -> -0.35202992 | F12: ='P&L assumptions'!F35 -> -0.33387156 | G12: ='P&L assumptions'!G35 -> -0.33842607 | H12: ='P&L assumptions'!I35 -> -0.3 | I12: ='P&L assumptions'!J35 -> -0.3 | J12: ='P&L assumptions'!K35 -> -0.3 | K12: ='P&L assumptions'!L35 -> -0.3 | L12: ='P&L assumptions'!M35 -> -0.3
B14: Net Operating Profit After Taxes (NOPAT) | C14: =SUM(C10:C11) -> 12022.565 | D14: =SUM(D10:D11) -> 9428.8171 | E14: =SUM(E10:E11) -> 9974.5922 | F14: =SUM(F10:F11) -> 12113.079 | G14: =SUM(G10:G11) -> 15351.36 | H14: =SUM(H10:H11) -> 17088.781 | I14: =SUM(I10:I11) -> 18797.147 | J14: =SUM(J10:J11) -> 20676.297 | ... L14: =SUM(L10:L11) -> 25016.955

Sheet BS
B1: Balance Sheet
B3: INR in Millions | C3: FY14 Actual | D3: FY15 Actual | E3: FY16 Actual | F3: FY17 Actual | G3: FY18 Actual | H3: FY19 Forecast | I3: FY20 Forecast | J3: FY21 Forecast | K3: FY22 Forecast | L3: FY23 Forecast | N3: Note
B4: Property, plant and equipment | D4: =C7 -> 34214.2 | E4: =D7 -> 31286.4 | F4: =E7 -> 29183.1 | G4: =F7 -> 27103.4 | H4: =G7 -> 25058.2 | I4: =H7 -> 23175.152 | J4: =I7 -> 22128.574 | K4: =J7 -> 22128.574 | L4: =K7 -> 22128.574
B5: Depreciation | C5: ='P&L assumptions'!C28 -> -3375.4 | D5: ='P&L assumptions'!D28 -> -3472.6 | E5: ='P&L assumptions'!E28 -> -3536.7 | F5: ='P&L assumptions'!F28 -> -3422.5 | G5: ='P&L assumptions'!G28 -> -3356.7 | H5: ='P&L assumptions'!I28 -> -4367.2792 | I5: ='P&L assumptions'!J28 -> -4803.8761 | J5: ='P&L assumptions'!K28 -> -5284.1196 | K5: ='P&L assumptions'!L28 -> -5812.3731 | L5: ='P&L assumptions'!M28 -> -6393.436
B6: Capex | D6: =D7-D4-D5 -> 544.8 | E6: =E7-E4-E5 -> 1433.4 | F6: =F7-F4-F5 -> 1342.8 | G6: =G7-G4-G5 -> 1311.5 | H6: ='BS assumptions'!H14 -> 2484.2316 | I6: ='BS assumptions'!I14 -> 3757.2979 | J6: ='BS assumptions'!J14 -> 5284.1196 | K6: ='BS assumptions'!K14 -> 5812.3731 | L6: ='BS assumptions'!L14 -> 6393.436
B7: Ending Value | C7: ='BS assumptions'!C13 -> 34214.2 | D7: ='BS assumptions'!D13 -> 31286.4 | E7: ='BS assumptions'!E13 -> 29183.1 | F7: ='BS assumptions'!F13 -> 27103.4 | G7: ='BS assumptions'!G13 -> 25058.2 | H7: =SUM(H4:H6) -> 23175.152 | I7: =SUM(I4:I6) -> 22128.574 | J7: =SUM(J4:J6) -> 22128.574 | K7: =SUM(K4:K6) -> 22128.574 | L7: =SUM(L4:L6) -> 22128.574
B9: Inventory | C9: ='BS assumptions'!C10 -> 8441 | D9: ='BS assumptions'!D10 -> 8208.1 | E9: ='BS assumptions'!E10 -> 9400.6 | F9: ='BS assumptions'!F10 -> 9024.7 | G9: ='BS assumptions'!G10 -> 9655.5 | H9: ='BS assumptions'!H10 -> 11339.62 | I9: ='BS assumptions'!I10 -> 12473.241 | J9: ='BS assumptions'!J10 -> 13720.191 | ... L9: ='BS assumptions'!L10 -> 16600.526
B10: Trade receivable | C10: ='BS assumptions'!C4 -> 991 | D10: ='BS assumptions'!D4 -> 784.2 | E10: ='BS assumptions'!E4 -> 979.3 | F10: ='BS assumptions'!F4 -> 889.7 | G10: ='BS assumptions'!G4 -> 1245.9 | H10: ='BS assumptions'!H4 -> 1249.1417 | I10: ='BS assumptions'!I4 -> 1374.0184 | J10: ='BS assumptions'!J4 -> 1511.379 | ... L10: ='BS assumptions'!L4 -> 1828.6689
B11: Trade payable | C11: ='BS assumptions'!C7 -> 7287.1 | D11: ='BS assumptions'!D7 -> 7494.1 | E11: ='BS assumptions'!E7 -> 7991.6 | F11: ='BS assumptions'!F7 -> 9846.4 | G11: ='BS assumptions'!G7 -> 12403.7 | H11: ='BS assumptions'!H7 -> 11302.849 | I11: ='BS assumptions'!I7 -> 12432.795 | J11: ='BS assumptions'!J7 -> 13675.701 | ... L11: ='BS assumptions'!L7 -> 16546.696
B12: Working Capital | C12: =SUM(C9:C10)-C11 -> 2144.9 | D12: =SUM(D9:D10)-D11 -> 1498.2 | E12: =SUM(E9:E10)-E11 -> 2388.3 | F12: =SUM(F9:F10)-F11 -> 68 | G12: =SUM(G9:G10)-G11 -> -1502.3 | H12: =SUM(H9:H10)-H11 -> 1285.9123 | I12: =SUM(I9:I10)-I11 -> 1414.465 | J12: =SUM(J9:J10)-J11 -> 1555.8691 | ... L12: =SUM(L9:L10)-L11 -> 1882.4989
B13: Change In Working Capital | D13: =D12-C12 -> -646.7 | E13: =E12-D12 -> 890.1 | F13: =F12-E12 -> -2320.3 | G13: =G12-F12 -> -1570.3 | H13: =H12-G12 -> 2788.2123 | I13: =I12-H12 -> 128.55266 | J13: =J12-I12 -> 141.40407 | K13: =K12-J12 -> 155.54023 | L13: =L12-K12 -> 171.08959

Sheet Cash Flow
B1: Cash Flow
B3: INR in Millions | C3: FY15 Actual | D3: FY16 Actual | E3: FY17 Actual | F3: FY18 Actual | G3: FY19 Forecast | H3: FY20 Forecast | I3: FY21 Forecast | J3: FY22 Forecast | K3: FY23 Forecast | M3: Note
B4: NOPAT | C4: ='P&L'!D14 -> 9428.8171 | D4: ='P&L'!E14 -> 9974.5922 | E4: ='P&L'!F14 -> 12113.079 | F4: ='P&L'!G14 -> 15351.36 | G4: ='P&L'!H14 -> 17088.781 | H4: ='P&L'!I14 -> 18797.147 | I4: ='P&L'!J14 -> 20676.297 | J4: ='P&L'!K14 -> 22743.307 | K4: ='P&L'!L14 -> 25016.955
B5: Add: Deprecitaion & Amortization | C5: =-('P&L assumptions'!D28) -> 3472.6 | D5: =-('P&L assumptions'!E28) -> 3536.7 | E5: =-('P&L assumptions'!F28) -> 3422.5 | F5: =-('P&L assumptions'!G28) -> 3356.7 | G5: =-'P&L assumptions'!I28 -> 4367.2792 | H5: =-'P&L assumptions'!J28 -> 4803.8761 | I5: =-'P&L assumptions'!K28 -> 5284.1196 | J5: =-'P&L assumptions'!L28 -> 5812.3731 | K5: =-'P&L assumptions'!M28 -> 6393.436
B6: Gross Cash Flow | C6: =SUM(C4:C5) -> 12901.417 | D6: =SUM(D4:D5) -> 13511.292 | E6: =SUM(E4:E5) -> 15535.579 | F6: =SUM(F4:F5) -> 18708.06 | G6: =SUM(G4:G5) -> 21456.06 | H6: =SUM(H4:H5) -> 23601.023 | I6: =SUM(I4:I5) -> 25960.417 | J6: =SUM(J4:J5) -> 28555.68 | K6: =SUM(K4:K5) -> 31410.391
B7: Less: Capex | C7: =-(BS!D6) -> -544.8 | D7: =-(BS!E6) -> -1433.4 | E7: =-(BS!F6) -> -1342.8 | F7: =-(BS!G6) -> -1311.5 | G7: =-(BS!H6) -> -2484.2316 | H7: =-(BS!I6) -> -3757.2979 | I7: =-(BS!J6) -> -5284.1196 | J7: =-(BS!K6) -> -5812.3731 | K7: =-(BS!L6) -> -6393.436
B8: Less: Investment in working capital | C8: =-(BS!D13) -> 646.7 | D8: =-(BS!E13) -> -890.1 | E8: =-(BS!F13) -> 2320.3 | F8: =-(BS!G13) -> 1570.3 | G8: =-(BS!H13) -> -2788.2123 | H8: =-(BS!I13) -> -128.55266 | I8: =-(BS!J13) -> -141.40407 | J8: =-(BS!K13) -> -155.54023 | K8: =-(BS!L13) -> -171.08959
B9: Net Cash Flow | C9: =SUM(C6:C8) -> 13003.317 | D9: =SUM(D6:D8) -> 11187.792 | E9: =SUM(E6:E8) -> 16513.079 | F9: =SUM(F6:F8) -> 18966.86 | G9: =SUM(G6:G8) -> 16183.616 | H9: =SUM(H6:H8) -> 19715.172 | I9: =SUM(I6:I8) -> 20534.893 | J9: =SUM(J6:J8) -> 22587.766 | K9: =SUM(K6:K8) -> 24845.865

Sheet DCF valuation
B1: DCF Valuation
G2: Possible Cases | H2: Pessimistic | I2: 0.01
B3: WACC | C3: =WACC!C22 -> 0.10972146 | H3: Base | I3: 0.02
B4: Terminal growth case selector | C4: 2 | H4: Optimistic | I4: 0.03
B6: INR in Millions | D6: FY15 Actual | E6: FY16 Actual | F6: FY17 Actual | G6: FY18 Actual | H6: FY19 Forecast | I6: FY20 Forecast | J6: FY21 Forecast | K6: FY22 Forecast | L6: FY23 Forecast | M6: Note
B7: Net Cash Flow | D7: ='Cash Flow'!C9 -> 13003.317 | E7: ='Cash Flow'!D9 -> 11187.792 | F7: ='Cash Flow'!E9 -> 16513.079 | G7: ='Cash Flow'!F9 -> 18966.86 | H7: ='Cash Flow'!G9 -> 16183.616 | I7: ='Cash Flow'!H9 -> 19715.172 | J7: ='Cash Flow'!I9 -> 20534.893 | K7: ='Cash Flow'!J9 -> 22587.766 | L7: ='Cash Flow'!K9 -> 24845.865
B8: Discount Factor | H8: =1/(1+$C$3)^1 -> 0.90112703 | I8: =1/(1+$C$3)^2 -> 0.81202992 | J8: =1/(1+$C$3)^3 -> 0.73174211 | K8: =1/(1+$C$3)^4 -> 0.65939259 | L8: =1/(1+$C$3)^5 -> 0.59419649
B9: Present Value of Net Cash Flow | H9: =H7*H8 -> 14583.494 | I9: =I7*I8 -> 16009.31 | J9: =J7*J8 -> 15026.246 | K9: =K7*K8 -> 14894.206 | L9: =L7*L8 -> 14763.326
M11: Enterprise Value | N11: Terminal Growth Rate (%)
M12: WACC (%) | N12: =C17 -> 243113.72 | O12: 0.01 | P12: 0.02 | Q12: 0.03 | R12: 0.04 | S12: 0.05 | T12: 0.06
B13: DCF Value | C13: =SUM(H9:L9) -> 75276.582 | D13: =C13/C17 -> 0.30963527 | N13: =WACC!$C$22-0.015 -> 0.094721458 | O13: 266809.75 | P13: 294137.31 | Q13: 329909.54 | R13: 378756.06 | S13: 449447.37 | T13: 560857.76
B14: Chosen Terminal Growth Rate | C14: =CHOOSE(C4,I2,I3,I4) -> 0.02 | N14: =WACC!$C$22-0.01 -> 0.099721458 | O14: 251234.47 | P14: 274983.83 | Q14: 305545.82 | R14: 346342.65 | S14: 403549.64 | T14: 489560.7
B15: Continuing Value | C15: =(L7*(1+C14))/(C3-C14) -> 282460.67 | N15: =WACC!$C$22-0.005 -> 0.10472146 | O15: 237315.23 | P15: 258102.68 | Q15: 284454.11 | R15: 318948.57 | S15: 366050.32 | T15: 434216.56
B16: Present Value of Continuing Value | C16: =C15*L8 -> 167837.14 | D16: =C16/C17 -> 0.69036473 | N16: =WACC!$C$22 -> 0.10972146 | O16: 224802.67 | P16: 243113.72 | Q16: 266018.52 | R16: 295493.71 | S16: 334839.77 | T16: 390012.44
B17: Enterprise Value | C17: =C13+C16 -> 243113.72 | N17: =WACC!$C$22+0.005 -> 0.11472146 | O17: 213495.05 | P17: 229717.06 | Q17: 249768.56 | R17: 275187.06 | S17: 308460.3 | T17: 353894.48
N18: =WACC!$C$22+0.01 -> 0.11972146 | O18: 203227.43 | P18: 217672.98 | Q18: 235338.61 | R18: 257436.08 | S18: 285872.34 | T18: 323831.56
B20: Less: Debt | C20: ='BS Source'!G28+'BS Source'!G36 -> 351.4
B21: Less: Provisions (employee benefits and contingencies) | C21: ='BS Source'!G31+'BS Source'!G40 -> 26221.8 | D21: Provisions of ₹26,221.8m treated as debt-like. Note 37 of the FY2018 annual report (p.69) gives the contingency provision as ₹7,482.2m litigation plus ₹1,190.8m other; the balance is employee benefit obligations. Both rank ahead of shareholders.
B22: Add: Cash and Cash Equivalents | C22: ='BS Source'!G15 -> 16100.6
B23: Add: Investments (non-current) | C23: ='BS Source'!G10 -> 7333.6
B24: Add: Loans | C24: ='BS Source'!G11 -> 401.4
B25: Add: Investments (current) | C25: ='BS Source'!G16 -> 19251.3
B26: Add: Other non-operating financial assets | C26: ='BS Source'!G21 -> 703.8
B27: Equity value | C27: =C17-C20-C21+SUM(C22:C26) -> 260331.22
B28: Number of Shares | C28: =WACC!C25 -> 96.415716
B29: Value of Per Equity Share | C29: =C27/C28 -> 2700.0911 | M29: Value per Equity Share | N29: Terminal Growth Rate (%)
M30: WACC (%) | N30: =C29 -> 2700.0911 | O30: 0.01 | P30: 0.02 | Q30: 0.03 | R30: 0.04 | S30: 0.05 | T30: 0.06
N31: =WACC!$C$22-0.015 -> 0.094721458 | O31: 2945.8605 | P31: 3229.2952 | Q31: 3600.3159 | R31: 4106.94 | S31: 4840.1328 | T31: 5995.6538
B32: Reconciliation to Market Price | N32: =WACC!$C$22-0.01 -> 0.099721458 | O32: 2784.3176 | P32: 3030.64 | Q32: 3347.6214 | R32: 3770.7561 | S32: 4364.0929 | T32: 5256.1783
B33: Market price per share (INR, 31 Dec 2018) | C33: =WACC!C26 -> 11107 | N33: =WACC!$C$22-0.005 -> 0.10472146 | O33: 2639.9506 | P33: 2855.5529 | Q33: 3128.8635 | R33: 3486.6315 | S33: 3975.1592 | T33: 4682.1626
B34: Shares outstanding (millions) | C34: =C28 -> 96.415716 | N34: =WACC!$C$22 -> 0.10972146 | O34: 2510.1734 | P34: 2700.0911 | Q34: 2937.6541 | R34: 3243.3634 | S34: 3651.4511 | T34: 4223.6883
B35: Market capitalisation | C35: =C33*C34 -> 1070889.4 | N35: =WACC!$C$22+0.005 -> 0.11472146 | O35: 2392.8936 | P35: 2561.1443 | Q35: 2769.1135 | R35: 3032.7479 | S35: 3377.8497 | T35: 3849.0819
B36: Add: Debt | C36: =C20 -> 351.4 | N36: =WACC!$C$22+0.01 -> 0.11972146 | O36: 2286.4004 | P36: 2436.2261 | Q36: 2619.4496 | R36: 2848.6391 | S36: 3143.573 | T36: 3537.2766
B37: Add: Provisions (debt-like) | C37: =C21 -> 26221.8
B38: Less: Non-operating assets | C38: =-SUM(C22:C26) -> -43790.7
B39: Market-implied Enterprise Value | C39: =SUM(C35:C38) -> 1053671.9
B40: Less: PV of explicit forecast cash flow | C40: =-C13 -> -75276.582
B41: Market-implied PV of continuing value | C41: =C39+C40 -> 978395.28
B42: Market-implied continuing value at FY23 | C42: =C41/L8 -> 1646585.4
B43: Market-implied terminal growth rate | C43: =(C42*C3-L7)/(C42+L7) -> 0.093225422
...

Sheet WACC
B2: Cost of Capital | D2: Comments | F2: Date | G2: Nestle Share price | H2: NSE50 Share Price | I2: Nestle monthly Share price % | J2: NSE50 monthly Share price % | K2: Comments | N2: Nestle India (INR) | O2: Date | P2: Nifty 50 | Q2: Monthly return - Nestle | R2: Monthly return - Nifty 50
B4: Key Inputs: | F4: 41640 | G4: 248.52 | H4: 6089.5 | K4: This price series is Nestle India unadjusted for the 2024 share split, retained as the source for the market price input in C26. Beta is regressed on the split-adjusted price block to the right.
B5: Total Equity to Capital | C5: =C27/SUM(C27,C29) -> 0.99967197 | F5: 41671 | G5: 239.53 | H5: 6276.95 | I5: =G5/G4-1 -> -0.036174151 | J5: =H5/H4-1 -> 0.030782494
B6: Debt to Capital | C6: =1-C5 -> 0.00032803083 | F6: 41699 | G6: 247.62 | H6: 6704.2 | I6: =G6/G5-1 -> 0.033774475 | J6: =H6/H5-1 -> 0.068066497
F7: 41730 | G7: 234.82 | H7: 6696.4 | I7: =G7/G6-1 -> -0.051692109 | J7: =H7/H6-1 -> -0.0011634498
B8: Calculations: | F8: 41760 | G8: 244.28 | H8: 7229.95 | I8: =G8/G7-1 -> 0.040286177 | J8: =H8/H7-1 -> 0.07967714
B9: Risk Free Rate | C9: 0.06733 | F9: 41791 | G9: 242.74 | H9: 7611.35 | I9: =G9/G8-1 -> -0.006304241 | J9: =H9/H8-1 -> 0.052752785
B10: Equity Beta | C10: =SLOPE(I5:I63,J5:J63) -> 0.84815875 | D10: Nestle India monthly returns regressed on the Nifty 50, Jan 2014 to Dec 2018, the 60 months ending at the valuation date. Prices from Investing.com. | F10: 41821 | G10: 252.52 | H10: 7721.3 | I10: =G10/G9-1 -> 0.040290022 | J10: =H10/H9-1 -> 0.014445532
B11: Market Risk Premium | C11: 0.05 | F11: 41852 | G11: 296.85 | H11: 7954.35 | I11: =G11/G10-1 -> 0.17555045 | J11: =H11/H10-1 -> 0.030182741
B12: Cost of Equity | C12: =C9+C10*C11 -> 0.10973794 | F12: 41883 | G12: 293.9 | H12: 7964.8 | I12: =G12/G11-1 -> -0.009937679 | J12: =H12/H11-1 -> 0.0013137466
F13: 41913 | G13: 308.1 | H13: 8322.2 | I13: =G13/G12-1 -> 0.048315754 | J13: =H13/H12-1 -> 0.044872439
B14: Pre-tax cost of debt | C14: 0.085 | F14: 41944 | G14: 305.49 | H14: 8588.25 | I14: =G14/G13-1 -> -0.0084712756 | J14: =H14/H13-1 -> 0.03196871
B15: Marginal Tax Rate | C15: =-('P&L assumptions'!I35) -> 0.3 | F15: 41974 | G15: 314.39 | H15: 8282.7 | I15: =G15/G14-1 -> 0.029133523 | J15: =H15/H14-1 -> -0.035577679
B16: Cost of Debt | C16: =C14*(1-C15) -> 0.0595 | F16: 42005 | G16: 350.25 | H16: 8808.9 | I16: =G16/G15-1 -> 0.11406215 | J16: =H16/H15-1 -> 0.063530008
F17: 42036 | G17: 345.86 | H17: 8901.85 | I17: =G17/G16-1 -> -0.012533904 | J17: =H17/H16-1 -> 0.010551828
F18: 42064 | G18: 342.09 | H18: 8491 | I18: =G18/G17-1 -> -0.010900364 | J18: =H18/H17-1 -> -0.046153328
B19: Weighted Cost of Equity | C19: =IF(ISNUMBER($C$5*$C$12),$C$5*$C$12,"n/a") -> 0.10970194 | F19: 42095 | G19: 323.63 | H19: 8181.5 | I19: =G19/G18-1 -> -0.053962408 | J19: =H19/H18-1 -> -0.036450359
B20: Weighted Cost of Debt | C20: =IF(ISNUMBER($C$6*$C$16),$C$6*$C$16,"n/a") -> 1.9517835e-05 | F20: 42125 | G20: 332.45 | H20: 8433.65 | I20: =G20/G19-1 -> 0.027253345 | J20: =H20/H19-1 -> 0.030819532
F21: 42156 | G21: 312.78 | H21: 8368.5 | I21: =G21/G20-1 -> -0.059166792 | J21: =H21/H20-1 -> -0.0077250064
B22: Weighted Average Cost of Capital | C22: =IF(ISNUMBER(C19+C20),(C19+C20),"n/a") -> 0.10972146 | F22: 42186 | G22: 313.04 | H22: 8532.85 | I22: =G22/G21-1 -> 0.0008312552 | J22: =H22/H21-1 -> 0.019639123
F23: 42217 | G23: 293.74 | H23: 7971.3 | I23: =G23/G22-1 -> -0.061653463 | J23: =H23/H22-1 -> -0.065810368
F24: 42248 | G24: 313.54 | H24: 7948.9 | I24: =G24/G23-1 -> 0.06740655 | J24: =H24/H23-1 -> -0.0028100812
B25: Shares outstanding | C25: 96.415716 | F25: 42278 | G25: 304 | H25: 8065.8 | I25: =G25/G24-1 -> -0.03042674 | J25: =H25/H24-1 -> 0.014706437
B26: Per Share price (Not in Millions) | C26: 11107 | D26: Closing price on 31 December 2018 (source: Investing.com). The series used for the beta regression is adjusted for the 2024 share split and for dividends, which is why it shows a different level for the same date. Adjusted prices are the correct input for a returns regression; the actual traded price is the correct input for market capitalisation. | F26: 42309 | G26: 288.49 | H26: 7935.25 | I26: =G26/G25-1 -> -0.051019737 | J26: =H26/H25-1 -> -0.016185623
B27: Total Equity Value | C27: =C25*C26 -> 1070889.4 | F27: 42339 | G27: 286.97 | H27: 7946.35 | I27: =G27/G26-1 -> -0.0052688135 | J27: =H27/H26-1 -> 0.0013988217
F28: 42370 | G28: 270.23 | H28: 7563.55 | I28: =G28/G27-1 -> -0.058333624 | J28: =H28/H27-1 -> -0.048173061
B29: Debt | C29: ='BS Source'!G28+'BS Source'!G36 -> 351.4 | F29: 42401 | G29: 246.59 | H29: 6987.05 | I29: =G29/G28-1 -> -0.087481035 | J29: =H29/H28-1 -> -0.076220822
F30: 42430 | G30: 283.49 | H30: 7738.4 | I30: =G30/G29-1 -> 0.1496411 | J30: =H30/H29-1 -> 0.10753465
F31: 42461 | G31: 281.92 | H31: 7849.8 | I31: =G31/G30-1 -> -0.0055381142 | J31: =H31/H30-1 -> 0.014395741
F32: 42491 | G32: 300.23 | H32: 8160.1 | I32: =G32/G31-1 -> 0.064947503 | J32: =H32/H31-1 -> 0.03952967
F33: 42522 | G33: 319.68 | H33: 8287.75 | I33: =G33/G32-1 -> 0.064783666 | J33: =H33/H32-1 -> 0.015643191
F34: 42552 | G34: 353.95 | H34: 8638.5 | I34: =G34/G33-1 -> 0.10720095 | J34: =H34/H33-1 -> 0.042321499
F35: 42583 | G35: 321.32 | H35: 8786.2 | I35: =G35/G34-1 -> -0.092188162 | J35: =H35/H34-1 -> 0.017097876
F36: 42614 | G36: 316.75 | H36: 8611.15 | I36: =G36/G35-1 -> -0.014222582 | J36: =H36/H35-1 -> -0.019923289
F37: 42644 | G37: 341.74 | H37: 8625.7 | I37: =G37/G36-1 -> 0.078895028 | J37: =H37/H36-1 -> 0.0016896698
F38: 42675 | G38: 309.7 | H38: 8224.5 | I38: =G38/G37-1 -> -0.093755487 | J38: =H38/H37-1 -> -0.046512167
F39: 42705 | G39: 296.84 | H39: 8185.8 | I39: =G39/G38-1 -> -0.041524056 | J39: =H39/H38-1 -> -0.0047054532
F40: 42736 | G40: 288.14 | H40: 8561.3 | I40: =G40/G39-1 -> -0.029308719 | J40: =H40/H39-1 -> 0.04587212
F41: 42767 | G41: 307.96 | H41: 8879.6 | I41: =G41/G40-1 -> 0.068786007 | J41: =H41/H40-1 -> 0.037178933
... F63: 43435 | G63: 545.82 | H63: 10862.55 | I63: =G63/G62-1 -> 0.029732483 | J63: =H63/H62-1 -> -0.001305537

Sheet 3.Sources -->
B11: 3.Sources -->

Sheet P&L Source
A1: Source: Nestlé India Annual Report 2018, standalone financial statements.
B2: Income Statement
B3: INR (Millions)
B5: Particulars | C5: 41974 | D5: 42339 | E5: 42705 | F5: 43070 | G5: 43435
B6: Sales | C6: 101295 | D6: 84304.4 | E6: 94096 | F6: 101351.1 | G6: 112162.3
B7: Other operating revenues | C7: =485.7 -> 485.7 | D7: 520.4 | E7: 649.7 | F7: 570.7 | G7: 760.4
B8: Excise Duties | C8: -3232.3 | D8: -3071.7 | E8: -3332.3 | F8: =-1825.8 -> -1825.8 | G8: 0
B9: Net Revenue | C9: =SUM(C6:C8) -> 98548.4 | D9: =SUM(D6:D8) -> 81753.1 | E9: =SUM(E6:E8) -> 91413.4 | F9: =SUM(F6:F8) -> 100096 | G9: =SUM(G6:G8) -> 112922.7 | H9: Operating item
B10: Operating expenses
B11: Cost of materials consumed | C11: =-44825.4-1088.5+674.3 -> -45239.6 | D11: =-33588.7-980.7-119.7 -> -34689.1 | E11: =-37750.9-1153.8+76.6 -> -38828.1 | F11: =(-42316-1747.6+795.6) -> -43268 | G11: =(-43656.8-2305.6+60.1) -> -45902.3 | H11: Operating item
B12: Marketing & Other Operating Expenses | C12: =-7722.2-23840.3-364.3 -> -31926.8 | D12: =-8374.3-21264.3- 333.1 -> -29971.7 | E12: =-9015.7-22954.6-1684.7 -> -33655 | F12: =(-10174.5-24170.2-876.5) -> -35221.2 | G12: =(-11241.5-28181.1-1036.8) -> -40459.4 | H12: Operating item
B13: Total operating expenses | C13: =SUM(C11:C12) -> -77166.4 | D13: =SUM(D11:D12) -> -64660.8 | E13: =SUM(E11:E12) -> -72483.1 | F13: =SUM(F11:F12) -> -78489.2 | G13: =SUM(G11:G12) -> -86361.7
B14: EBITDA | C14: =C9+C13 -> 21382 | D14: =D9+D13 -> 17092.3 | E14: =E9+E13 -> 18930.3 | F14: =F9+F13 -> 21606.8 | G14: =G9+G13 -> 26561
B15: Depreciation and amortisation expenses | C15: -3375.4 | D15: -3472.6 | E15: -3536.7 | F15: -3422.5 | G15: -3356.7 | H15: Operating item
B16: EBIT | C16: =C14+C15 -> 18006.6 | D16: =D14+D15 -> 13619.7 | E16: =E14+E15 -> 15393.6 | F16: =F14+F15 -> 18184.3 | G16: =G14+G15 -> 23204.3
B17: Other Income | C17: =873.2 -> 873.2 | D17: =1100.9 -> 1100.9 | E17: 1509 | F17: 1769.2 | G17: 2589.2 | H17: Non Operating item
B18: Interest charges | C18: =-142.3 -> -142.3 | D18: -32.9 | E18: -909.1 | F18: -919 | G18: -1119.5 | H18: Non Operating item
B19: Other non operating items | C19: =-81.1-648.3-249.5+70-85.1 -> -994 | D19: =-282.2-301.5-753.2-5008.4-206.1 -> -6551.4 | E19: =-118.3-313.6-107.8 -> -539.7 | F19: =(-371.8-269.1) -> -640.9 | G19: =(-110.8-273.7) -> -384.5 | H19: Non Operating item
B20: Profit before tax | C20: =C16+SUM(C17:C19) -> 17743.5 | D20: =D16+SUM(D17:D19) -> 8136.3 | E20: =E16+SUM(E17:E19) -> 15453.8 | F20: =F16+SUM(F17:F19) -> 18393.6 | G20: =G16+SUM(G17:G19) -> 24289.5
B21: Tax expense | C21: -5896.6 | D21: -2503.6 | E21: -5440.2 | F21: -6141.1 | G21: -8220.2 | H21: Operating item
B22: Profit after tax / Net profit | C22: =SUM(C20:C21) -> 11846.9 | D22: =SUM(D20:D21) -> 5632.7 | E22: =SUM(E20:E21) -> 10013.6 | F22: =SUM(F20:F21) -> 12252.5 | G22: =SUM(G20:G21) -> 16069.3

Sheet BS Source
A1: Source: Nestlé India Annual Report 2018, standalone financial statements.
B2: Balance Sheet
B3: INR (Millions)
B5: Particulars | C5: 41974 | D5: 42339 | E5: 42705 | F5: 43070 | G5: 43435
B6: ASSETS
B7: NON-CURRENT ASSETS
B8: Net PP&E | C8: 34214.2 | D8: 31286.4 | E8: 29183.1 | F8: 27103.4 | G8: 25058.2 | H8: Operating item
B9: Other non-current assets | D9: 676.9 | E9: 706.7 | F9: 832.3 | G9: 718.1 | H9: Operating item
B10: Investments | C10: 3044.6 | D10: 3417.8 | E10: 4743.1 | F10: 5852.8 | G10: 7333.6 | H10: Non Operating item
B11: Loans | C11: 1299.5 | D11: 627.4 | E11: 643.7 | F11: 463.5 | G11: 401.4 | H11: Non Operating item
B12: Total Non-Current Assets | C12: =SUM(C8:C11) -> 38558.3 | D12: =SUM(D8:D11) -> 36008.5 | E12: =SUM(E8:E11) -> 35276.6 | F12: =SUM(F8:F11) -> 34252 | G12: =SUM(G8:G11) -> 33511.3
B14: CURRENT ASSETS
B15: Cash and Cash Equivalents | C15: 4458.2 | D15: =4892.7+102.8 -> 4995.5 | E15: =8693.2+106.8 -> 8800 | F15: =(14476.9+97.3) -> 14574.2 | G15: =(15987.7+112.9) -> 16100.6 | H15: Operating item
B16: Investments | C16: 5073.6 | D16: 9879.4 | E16: 12813.5 | F16: 13935.9 | G16: 19251.3 | H16: Excluded from operating working capital; added back in equity bridge
B17: Inventories | C17: 8441 | D17: 8208.1 | E17: 9400.6 | F17: 9024.7 | G17: 9655.5 | H17: Operating item
B18: Trade Receivables | C18: 991 | D18: 784.2 | E18: 979.3 | F18: 889.7 | G18: 1245.9 | H18: Operating item
B19: Other current assets | C19: 152.2 | D19: =304.8 -> 304.8 | E19: =314.6 -> 314.6 | F19: =169.6 -> 169.6 | G19: =(223.9) -> 223.9 | H19: Operating item
B20: Current tax assets | C20: 0 | D20: =327.6 -> 327.6 | E20: =27.3 -> 27.3 | F20: 63.9 | G20: 188.5 | H20: Operating item
B21: Other non operating financial assets | C21: 520.7 | D21: =181.7+222.7 -> 404.4 | E21: =166+326.7 -> 492.7 | F21: =(288+427.9) -> 715.9 | G21: =(178.9+524.9) -> 703.8 | H21: Non-Operating item
B22: Total Current Assets | C22: =SUM(C15:C21) -> 19636.7 | D22: =SUM(D15:D21) -> 24904 | E22: =SUM(E15:E21) -> 32828 | F22: =SUM(F15:F21) -> 39373.9 | G22: =SUM(G15:G21) -> 47369.5
B23: TOTAL ASSETS | C23: =C12+C22 -> 58195 | D23: =D12+D22 -> 60912.5 | E23: =E12+E22 -> 68104.6 | F23: =F12+F22 -> 73625.9 | G23: =G12+G22 -> 80880.8
B25: Particulars | C25: 41974 | D25: 42339 | E25: 42705 | F25: 43070 | G25: 43435
B26: LIABILITIES
B27: NON-CURRENT LIABILITIES
B28: Long Term Debt | C28: 154.6 | D28: 167.9 | E28: 331.5 | F28: 351.4 | G28: 351.4 | H28: Non-Operating item
B29: Deferred Tax Liability | C29: 2227.2 | D29: 1747 | E29: 1553.4 | F29: 1219.6 | G29: 588.2 | H29: Non-Operating item
B30: Other non-current liabilities | C30: 0 | D30: 0 | E30: 6.8 | F30: 6 | G30: 5.1 | H30: Non-Operating item
B31: Provisions | C31: 13886.6 | D31: 15971.7 | E31: 19722.1 | F31: 22915.9 | G31: 24649.2 | H31: Non-Operating item
B32: Equity | C32: 28372.1 | D32: 30358.6 | E32: 32823.3 | F32: 34205.9 | G32: 36737.4 | H32: Non-Operating item
B33: Total Non-Current Liabilities | C33: =SUM(C28:C32) -> 44640.5 | D33: =SUM(D28:D32) -> 48245.2 | E33: =SUM(E28:E32) -> 54437.1 | F33: =SUM(F28:F32) -> 58698.8 | G33: =SUM(G28:G32) -> 62331.3
B35: CURRENT LIABILITIES
B36: Short Term Debt | C36: 41.1 | D36: 9.4 | E36: 0 | F36: 0 | G36: 0 | H36: Non-Operating item
B37: Other Financial Liabilities | C37: 0 | D37: 2492.7 | E37: 3116.4 | F37: 3140.2 | G37: 3161.8 | H37: Non-Operating item
B38: TradePayables | C38: 7287.1 | D38: 7494.1 | E38: 7991.6 | F38: 9846.4 | G38: 12403.7 | H38: Operating item
B39: Other current liabilities | C39: 4095.7 | D39: 2164.7 | E39: 2021.5 | F39: 1065.9 | G39: 1411.4 | H39: Operating item
B40: Provisions | C40: 2130.6 | D40: 506.4 | E40: 538 | F40: 874.6 | G40: 1572.6 | H40: Operating item
B41: Total Current Liabilities | C41: =SUM(C36:C40) -> 13554.5 | D41: =SUM(D36:D40) -> 12667.3 | E41: =SUM(E36:E40) -> 13667.5 | F41: =SUM(F36:F40) -> 14927.1 | G41: =SUM(G36:G40) -> 18549.5
B42: TOTAL LIABILITIES | C42: =C33+C41 -> 58195 | D42: =D33+D41 -> 60912.5 | E42: =E33+E41 -> 68104.6 | F42: =F33+F41 -> 73625.9 | G42: =G33+G41 -> 80880.8
